Workbook

Sheet Kintoneデータ抽出

Sheet クライアント名あり（縦）
A1: キッズコーポレーション 運営実績
O3: 46029
G4: １，認可保育園・小規模保育事業等 | K4: ='地図版 '!N6 -> 0 | M4: 園
G5: ２，病院内保育園 | K5: ='地図版 '!N4 -> 0 | M5: 園
G6: ３，事業所内保育園 | K6: ='地図版 '!N5 -> 0 | M6: 園
G7: 合計稼働園数（開園予定含む） | K7: ='地図版 '!N3 -> 0 | M7: 園
G8: うち開園予定 | K8: ='地図版 '!N8 -> 0 | M8: 園
B10: １．認可保育園・小規模保育事業企画運営 | N10: 園
D11: No. | F11: 地域 | G11: クライアント名 | H11: 施設名 | I11: 定員数 | J11: 開園日 | K11: 形態
B12: 東 北 | D12: =IF(H12<>"",1,"") | F12: {=IFERROR(INDEX(Kintoneデータ抽出!A:A, _xlfn.AGGREGATE(15, 6, ROW(Kintoneデータ抽出!$K$2:$K$5000) / ((Kintoneデータ抽出!$K$2:$K$5000="小規模") + (Kintoneデータ抽出!$K$2:$K$5000="認可")), ROW(A1))), "")} | G12: {=IFERROR(INDEX(Kintoneデータ抽出!D:D, _xlfn.AGGREGATE(15, 6, ROW(Kintoneデータ抽出!$K$2:$K$5000) / ((Kintoneデータ抽出!$K$2:$K$5000="小規模") + (Kintoneデータ抽出!$K$2:$K$5000="認可")), ROW(A1))), "")} | H12: {=IFERROR(INDEX(Kintoneデータ抽出!C:C, _xlfn.AGGREGATE(15, 6, ROW(Kintoneデータ抽出!$K$2:$K$5000) / ((Kintoneデータ抽出!$K$2:$K$5000="小規模") + (Kintoneデータ抽出!$K$2:$K$5000="認可")), ROW(A1))), "")} | I12: {=IFERROR(IF(INDEX(Kintoneデータ抽出!G:G, _xlfn.AGGREGATE(15, 6, ROW(Kintoneデータ抽出!$K$2:$K$5000) / ((Kintoneデータ抽出!$K$2:$K$5000="小規模") + (Kintoneデータ抽出!$K$2:$K$5000="認可")), ROW(A1)))<>"",INDEX(Kintoneデータ抽出!G:G, _xlfn.AGGREGATE(15, 6, ROW(Kintoneデータ抽出!$K$2:$K$5000) / ((Kintoneデータ抽出!$K$2:$K$5000="小規模") + (Kintoneデータ抽出!$K$2:$K$5000="認可")), ROW(A1)))&"名",""), "")} | J12: {=IFERROR(IF(INDEX(Kintoneデータ抽出!E:E, _xlfn.AGGREGATE(15, 6, ROW(Kintoneデータ抽出!$K$2:$K$5000) / ((Kintoneデータ抽出!$K$2:$K$5000="小規模") + (Kintoneデータ抽出!$K$2:$K$5000="認可")), ROW(A1)))<>"", YEAR(INDEX(Kintoneデータ抽出!E:E, _xlfn.AGGREGATE(15, 6, ROW(Kintoneデータ抽出!$K$2:$K$5000) / ((Kintoneデータ抽出!$K$2:$K$5000="小規模") + (Kintoneデータ抽出!$K$2:$K$5000="認可")), ROW(A1))))&"年" &MONTH(INDEX(Kintoneデータ抽出!E:E, _xlfn.AGGREGATE(15, 6, ROW(Kintoneデータ抽出!$K$2:$K$5000) / ((Kintoneデータ抽出!$K$2:$K$5000="小規模") + (Kintoneデータ抽出!$K$2:$K$5000="認可")), ROW(A1))))&"月" &DAY(INDEX(Kintoneデータ抽出!E:E, _xlfn.AGGREGATE(15, 6, ROW(Kintoneデータ抽出!$K$2:$K$5000) / ((Kintoneデータ抽出!$K$2:$K$5000="小規模") + (Kintoneデータ抽出!$K$2:$K$5000="認可")), ROW(A1))))&"日",""), "")} | K12: {=IFERROR(IF(INDEX(Kintoneデータ抽出!F:F, _xlfn.AGGREGATE(15, 6, ROW(Kintoneデータ抽出!$K$2:$K$5000) / ((Kintoneデータ抽出!$K$2:$K$5000="小規模") + (Kintoneデータ抽出!$K$2:$K$5000="認可")), ROW(A1)))<>"", VLOOKUP(INDEX(Kintoneデータ抽出!F:F, _xlfn.AGGREGATE(15, 6, ROW(Kintoneデータ抽出!$K$2:$K$5000) / ((Kintoneデータ抽出!$K$2:$K$5000="小規模") + (Kintoneデータ抽出!$K$2:$K$5000="認可")), ROW(A1))),基本開園日の表記!$A$2:$B$13,2,FALSE),""), "")} | L12: {=IFERROR(IF(INDEX(Kintoneデータ抽出!F:F, _xlfn.AGGREGATE(15, 6, ROW(Kintoneデータ抽出!$K$2:$K$5000) / ((Kintoneデータ抽出!$K$2:$K$5000="小規模") + (Kintoneデータ抽出!$K$2:$K$5000="認可")), ROW(A1)))<>"", IF(COUNTIF(INDEX(Kintoneデータ抽出!F:F, _xlfn.AGGREGATE(15, 6, ROW(Kintoneデータ抽出!$K$2:$K$5000) / ((Kintoneデータ抽出!$K$2:$K$5000="小規模") + (Kintoneデータ抽出!$K$2:$K$5000="認可")), ROW(A1))),"*あり*"),"夜間",""),""), "")} | M12: {=IFERROR(IF(INDEX(Kintoneデータ抽出!I:I, _xlfn.AGGREGATE(15, 6, ROW(Kintoneデータ抽出!$K$2:$K$5000) / ((Kintoneデータ抽出!$K$2:$K$5000="小規模") + (Kintoneデータ抽出!$K$2:$K$5000="認可")), ROW(A1)))<>"", IF(COUNTIF(INDEX(Kintoneデータ抽出!I:I, _xlfn.AGGREGATE(15, 6, ROW(Kintoneデータ抽出!$K$2:$K$5000) / ((Kintoneデータ抽出!$K$2:$K$5000="小規模") + (Kintoneデータ抽出!$K$2:$K$5000="認可")), ROW(A1))),"*あり*"),"学童",""),""), "")} | N12: {=IFERROR(IF(INDEX(Kintoneデータ抽出!H:H, _xlfn.AGGREGATE(15, 6, ROW(Kintoneデータ抽出!$K$2:$K$5000) / ((Kintoneデータ抽出!$K$2:$K$5000="小規模") + (Kintoneデータ抽出!$K$2:$K$5000="認可")), ROW(A1)))<>"", IF(COUNTIF(INDEX(Kintoneデータ抽出!H:H, _xlfn.AGGREGATE(15, 6, ROW(Kintoneデータ抽出!$K$2:$K$5000) / ((Kintoneデータ抽出!$K$2:$K$5000="小規模") + (Kintoneデータ抽出!$K$2:$K$5000="認可")), ROW(A1))),"*あり*"),"病児",""),""), "")} | O12: {=IFERROR( IF(INDEX(Kintoneデータ抽出!M:M, _xlfn.AGGREGATE(15, 6, ROW(Kintoneデータ抽出!$K$2:$K$5000) / ((Kintoneデータ抽出!$K$2:$K$5000="小規模") + (Kintoneデータ抽出!$K$2:$K$5000="認可")), ROW(A1)))<>0,INDEX(Kintoneデータ抽出!M:M, _xlfn.AGGREGATE(15, 6, ROW(Kintoneデータ抽出!$K$2:$K$5000) / ((Kintoneデータ抽出!$K$2:$K$5000="小規模") + (Kintoneデータ抽出!$K$2:$K$5000="認可")), ROW(A1))),""), "")} | P12: {=IFERROR(IF(INDEX(Kintoneデータ抽出!L:L, _xlfn.AGGREGATE(15, 6, ROW(Kintoneデータ抽出!$K$2:$K$5000) / ((Kintoneデータ抽出!$K$2:$K$5000="院内")), ROW(A1)))<>"", IF(COUNTIF(INDEX(Kintoneデータ抽出!L:L, _xlfn.AGGREGATE(15, 6, ROW(Kintoneデータ抽出!$K$2:$K$5000) / ((Kintoneデータ抽出!$K$2:$K$5000="院内")), ROW(A1))),"*企業主導型以外*"),"", IF(COUNTIF(INDEX(Kintoneデータ抽出!L:L, _xlfn.AGGREGATE(15, 6, ROW(Kintoneデータ抽出!$K$2:$K$5000) / ((Kintoneデータ抽出!$K$2:$K$5000="院内")), ROW(A1))),"*その他*"),"", IF(COUNTIF(INDEX(Kintoneデータ抽出!L:L, _xlfn.AGGREGATE(15, 6, ROW(Kintoneデータ抽出!$K$2:$K$5000) / ((Kintoneデータ抽出!$K$2:$K$5000="院内")), ROW(A1))),"*新制度*"),"新制度","企業主導型"))),""), "")}
D13: =IF(H13<>"",D12+1,"") | F13: {=IFERROR(INDEX(Kintoneデータ抽出!A:A, _xlfn.AGGREGATE(15, 6, ROW(Kintoneデータ抽出!$K$2:$K$5000) / ((Kintoneデータ抽出!$K$2:$K$5000="小規模") + (Kintoneデータ抽出!$K$2:$K$5000="認可")), ROW(A2))), "")} | G13: {=IFERROR(INDEX(Kintoneデータ抽出!D:D, _xlfn.AGGREGATE(15, 6, ROW(Kintoneデータ抽出!$K$2:$K$5000) / ((Kintoneデータ抽出!$K$2:$K$5000="小規模") + (Kintoneデータ抽出!$K$2:$K$5000="認可")), ROW(A2))), "")} | H13: {=IFERROR(INDEX(Kintoneデータ抽出!C:C, _xlfn.AGGREGATE(15, 6, ROW(Kintoneデータ抽出!$K$2:$K$5000) / ((Kintoneデータ抽出!$K$2:$K$5000="小規模") + (Kintoneデータ抽出!$K$2:$K$5000="認可")), ROW(A2))), "")} | I13: {=IFERROR(IF(INDEX(Kintoneデータ抽出!G:G, _xlfn.AGGREGATE(15, 6, ROW(Kintoneデータ抽出!$K$2:$K$5000) / ((Kintoneデータ抽出!$K$2:$K$5000="小規模") + (Kintoneデータ抽出!$K$2:$K$5000="認可")), ROW(A2)))<>"",INDEX(Kintoneデータ抽出!G:G, _xlfn.AGGREGATE(15, 6, ROW(Kintoneデータ抽出!$K$2:$K$5000) / ((Kintoneデータ抽出!$K$2:$K$5000="小規模") + (Kintoneデータ抽出!$K$2:$K$5000="認可")), ROW(A2)))&"名",""), "")} | J13: {=IFERROR(IF(INDEX(Kintoneデータ抽出!E:E, _xlfn.AGGREGATE(15, 6, ROW(Kintoneデータ抽出!$K$2:$K$5000) / ((Kintoneデータ抽出!$K$2:$K$5000="小規模") + (Kintoneデータ抽出!$K$2:$K$5000="認可")), ROW(A2)))<>"", YEAR(INDEX(Kintoneデータ抽出!E:E, _xlfn.AGGREGATE(15, 6, ROW(Kintoneデータ抽出!$K$2:$K$5000) / ((Kintoneデータ抽出!$K$2:$K$5000="小規模") + (Kintoneデータ抽出!$K$2:$K$5000="認可")), ROW(A2))))&"年" &MONTH(INDEX(Kintoneデータ抽出!E:E, _xlfn.AGGREGATE(15, 6, ROW(Kintoneデータ抽出!$K$2:$K$5000) / ((Kintoneデータ抽出!$K$2:$K$5000="小規模") + (Kintoneデータ抽出!$K$2:$K$5000="認可")), ROW(A2))))&"月" &DAY(INDEX(Kintoneデータ抽出!E:E, _xlfn.AGGREGATE(15, 6, ROW(Kintoneデータ抽出!$K$2:$K$5000) / ((Kintoneデータ抽出!$K$2:$K$5000="小規模") + (Kintoneデータ抽出!$K$2:$K$5000="認可")), ROW(A2))))&"日",""), "")} | K13: {=IFERROR(IF(INDEX(Kintoneデータ抽出!F:F, _xlfn.AGGREGATE(15, 6, ROW(Kintoneデータ抽出!$K$2:$K$5000) / ((Kintoneデータ抽出!$K$2:$K$5000="小規模") + (Kintoneデータ抽出!$K$2:$K$5000="認可")), ROW(A2)))<>"", VLOOKUP(INDEX(Kintoneデータ抽出!F:F, _xlfn.AGGREGATE(15, 6, ROW(Kintoneデータ抽出!$K$2:$K$5000) / ((Kintoneデータ抽出!$K$2:$K$5000="小規模") + (Kintoneデータ抽出!$K$2:$K$5000="認可")), ROW(A2))),基本開園日の表記!$A$2:$B$13,2,FALSE),""), "")} | L13: {=IFERROR(IF(INDEX(Kintoneデータ抽出!F:F, _xlfn.AGGREGATE(15, 6, ROW(Kintoneデータ抽出!$K$2:$K$5000) / ((Kintoneデータ抽出!$K$2:$K$5000="小規模") + (Kintoneデータ抽出!$K$2:$K$5000="認可")), ROW(A2)))<>"", IF(COUNTIF(INDEX(Kintoneデータ抽出!F:F, _xlfn.AGGREGATE(15, 6, ROW(Kintoneデータ抽出!$K$2:$K$5000) / ((Kintoneデータ抽出!$K$2:$K$5000="小規模") + (Kintoneデータ抽出!$K$2:$K$5000="認可")), ROW(A2))),"*あり*"),"夜間",""),""), "")} | M13: {=IFERROR(IF(INDEX(Kintoneデータ抽出!I:I, _xlfn.AGGREGATE(15, 6, ROW(Kintoneデータ抽出!$K$2:$K$5000) / ((Kintoneデータ抽出!$K$2:$K$5000="小規模") + (Kintoneデータ抽出!$K$2:$K$5000="認可")), ROW(A2)))<>"", IF(COUNTIF(INDEX(Kintoneデータ抽出!I:I, _xlfn.AGGREGATE(15, 6, ROW(Kintoneデータ抽出!$K$2:$K$5000) / ((Kintoneデータ抽出!$K$2:$K$5000="小規模") + (Kintoneデータ抽出!$K$2:$K$5000="認可")), ROW(A2))),"*あり*"),"学童",""),""), "")} | N13: {=IFERROR(IF(INDEX(Kintoneデータ抽出!H:H, _xlfn.AGGREGATE(15, 6, ROW(Kintoneデータ抽出!$K$2:$K$5000) / ((Kintoneデータ抽出!$K$2:$K$5000="小規模") + (Kintoneデータ抽出!$K$2:$K$5000="認可")), ROW(A2)))<>"", IF(COUNTIF(INDEX(Kintoneデータ抽出!H:H, _xlfn.AGGREGATE(15, 6, ROW(Kintoneデータ抽出!$K$2:$K$5000) / ((Kintoneデータ抽出!$K$2:$K$5000="小規模") + (Kintoneデータ抽出!$K$2:$K$5000="認可")), ROW(A2))),"*あり*"),"病児",""),""), "")} | O13: {=IFERROR( IF(INDEX(Kintoneデータ抽出!M:M, _xlfn.AGGREGATE(15, 6, ROW(Kintoneデータ抽出!$K$2:$K$5000) / ((Kintoneデータ抽出!$K$2:$K$5000="小規模") + (Kintoneデータ抽出!$K$2:$K$5000="認可")), ROW(A2)))<>0,INDEX(Kintoneデータ抽出!M:M, _xlfn.AGGREGATE(15, 6, ROW(Kintoneデータ抽出!$K$2:$K$5000) / ((Kintoneデータ抽出!$K$2:$K$5000="小規模") + (Kintoneデータ抽出!$K$2:$K$5000="認可")), ROW(A2))),""), "")} | P13: {=IFERROR(IF(INDEX(Kintoneデータ抽出!L:L, _xlfn.AGGREGATE(15, 6, ROW(Kintoneデータ抽出!$K$2:$K$5000) / ((Kintoneデータ抽出!$K$2:$K$5000="院内")), ROW(A2)))<>"", IF(COUNTIF(INDEX(Kintoneデータ抽出!L:L, _xlfn.AGGREGATE(15, 6, ROW(Kintoneデータ抽出!$K$2:$K$5000) / ((Kintoneデータ抽出!$K$2:$K$5000="院内")), ROW(A2))),"*企業主導型以外*"),"", IF(COUNTIF(INDEX(Kintoneデータ抽出!L:L, _xlfn.AGGREGATE(15, 6, ROW(Kintoneデータ抽出!$K$2:$K$5000) / ((Kintoneデータ抽出!$K$2:$K$5000="院内")), ROW(A2))),"*その他*"),"", IF(COUNTIF(INDEX(Kintoneデータ抽出!L:L, _xlfn.AGGREGATE(15, 6, ROW(Kintoneデータ抽出!$K$2:$K$5000) / ((Kintoneデータ抽出!$K$2:$K$5000="院内")), ROW(A2))),"*新制度*"),"新制度","企業主導型"))),""), "")}
D14: =IF(H14<>"",D13+1,"") | F14: {=IFERROR(INDEX(Kintoneデータ抽出!A:A, _xlfn.AGGREGATE(15, 6, ROW(Kintoneデータ抽出!$K$2:$K$5000) / ((Kintoneデータ抽出!$K$2:$K$5000="小規模") + (Kintoneデータ抽出!$K$2:$K$5000="認可")), ROW(A3))), "")} | G14: {=IFERROR(INDEX(Kintoneデータ抽出!D:D, _xlfn.AGGREGATE(15, 6, ROW(Kintoneデータ抽出!$K$2:$K$5000) / ((Kintoneデータ抽出!$K$2:$K$5000="小規模") + (Kintoneデータ抽出!$K$2:$K$5000="認可")), ROW(A3))), "")} | H14: {=IFERROR(INDEX(Kintoneデータ抽出!C:C, _xlfn.AGGREGATE(15, 6, ROW(Kintoneデータ抽出!$K$2:$K$5000) / ((Kintoneデータ抽出!$K$2:$K$5000="小規模") + (Kintoneデータ抽出!$K$2:$K$5000="認可")), ROW(A3))), "")} | I14: {=IFERROR(IF(INDEX(Kintoneデータ抽出!G:G, _xlfn.AGGREGATE(15, 6, ROW(Kintoneデータ抽出!$K$2:$K$5000) / ((Kintoneデータ抽出!$K$2:$K$5000="小規模") + (Kintoneデータ抽出!$K$2:$K$5000="認可")), ROW(A3)))<>"",INDEX(Kintoneデータ抽出!G:G, _xlfn.AGGREGATE(15, 6, ROW(Kintoneデータ抽出!$K$2:$K$5000) / ((Kintoneデータ抽出!$K$2:$K$5000="小規模") + (Kintoneデータ抽出!$K$2:$K$5000="認可")), ROW(A3)))&"名",""), "")} | J14: {=IFERROR(IF(INDEX(Kintoneデータ抽出!E:E, _xlfn.AGGREGATE(15, 6, ROW(Kintoneデータ抽出!$K$2:$K$5000) / ((Kintoneデータ抽出!$K$2:$K$5000="小規模") + (Kintoneデータ抽出!$K$2:$K$5000="認可")), ROW(A3)))<>"", YEAR(INDEX(Kintoneデータ抽出!E:E, _xlfn.AGGREGATE(15, 6, ROW(Kintoneデータ抽出!$K$2:$K$5000) / ((Kintoneデータ抽出!$K$2:$K$5000="小規模") + (Kintoneデータ抽出!$K$2:$K$5000="認可")), ROW(A3))))&"年" &MONTH(INDEX(Kintoneデータ抽出!E:E, _xlfn.AGGREGATE(15, 6, ROW(Kintoneデータ抽出!$K$2:$K$5000) / ((Kintoneデータ抽出!$K$2:$K$5000="小規模") + (Kintoneデータ抽出!$K$2:$K$5000="認可")), ROW(A3))))&"月" &DAY(INDEX(Kintoneデータ抽出!E:E, _xlfn.AGGREGATE(15, 6, ROW(Kintoneデータ抽出!$K$2:$K$5000) / ((Kintoneデータ抽出!$K$2:$K$5000="小規模") + (Kintoneデータ抽出!$K$2:$K$5000="認可")), ROW(A3))))&"日",""), "")} | K14: {=IFERROR(IF(INDEX(Kintoneデータ抽出!F:F, _xlfn.AGGREGATE(15, 6, ROW(Kintoneデータ抽出!$K$2:$K$5000) / ((Kintoneデータ抽出!$K$2:$K$5000="小規模") + (Kintoneデータ抽出!$K$2:$K$5000="認可")), ROW(A3)))<>"", VLOOKUP(INDEX(Kintoneデータ抽出!F:F, _xlfn.AGGREGATE(15, 6, ROW(Kintoneデータ抽出!$K$2:$K$5000) / ((Kintoneデータ抽出!$K$2:$K$5000="小規模") + (Kintoneデータ抽出!$K$2:$K$5000="認可")), ROW(A3))),基本開園日の表記!$A$2:$B$13,2,FALSE),""), "")} | L14: {=IFERROR(IF(INDEX(Kintoneデータ抽出!F:F, _xlfn.AGGREGATE(15, 6, ROW(Kintoneデータ抽出!$K$2:$K$5000) / ((Kintoneデータ抽出!$K$2:$K$5000="小規模") + (Kintoneデータ抽出!$K$2:$K$5000="認可")), ROW(A3)))<>"", IF(COUNTIF(INDEX(Kintoneデータ抽出!F:F, _xlfn.AGGREGATE(15, 6, ROW(Kintoneデータ抽出!$K$2:$K$5000) / ((Kintoneデータ抽出!$K$2:$K$5000="小規模") + (Kintoneデータ抽出!$K$2:$K$5000="認可")), ROW(A3))),"*あり*"),"夜間",""),""), "")} | M14: {=IFERROR(IF(INDEX(Kintoneデータ抽出!I:I, _xlfn.AGGREGATE(15, 6, ROW(Kintoneデータ抽出!$K$2:$K$5000) / ((Kintoneデータ抽出!$K$2:$K$5000="小規模") + (Kintoneデータ抽出!$K$2:$K$5000="認可")), ROW(A3)))<>"", IF(COUNTIF(INDEX(Kintoneデータ抽出!I:I, _xlfn.AGGREGATE(15, 6, ROW(Kintoneデータ抽出!$K$2:$K$5000) / ((Kintoneデータ抽出!$K$2:$K$5000="小規模") + (Kintoneデータ抽出!$K$2:$K$5000="認可")), ROW(A3))),"*あり*"),"学童",""),""), "")} | N14: {=IFERROR(IF(INDEX(Kintoneデータ抽出!H:H, _xlfn.AGGREGATE(15, 6, ROW(Kintoneデータ抽出!$K$2:$K$5000) / ((Kintoneデータ抽出!$K$2:$K$5000="小規模") + (Kintoneデータ抽出!$K$2:$K$5000="認可")), ROW(A3)))<>"", IF(COUNTIF(INDEX(Kintoneデータ抽出!H:H, _xlfn.AGGREGATE(15, 6, ROW(Kintoneデータ抽出!$K$2:$K$5000) / ((Kintoneデータ抽出!$K$2:$K$5000="小規模") + (Kintoneデータ抽出!$K$2:$K$5000="認可")), ROW(A3))),"*あり*"),"病児",""),""), "")} | O14: {=IFERROR( IF(INDEX(Kintoneデータ抽出!M:M, _xlfn.AGGREGATE(15, 6, ROW(Kintoneデータ抽出!$K$2:$K$5000) / ((Kintoneデータ抽出!$K$2:$K$5000="小規模") + (Kintoneデータ抽出!$K$2:$K$5000="認可")), ROW(A3)))<>0,INDEX(Kintoneデータ抽出!M:M, _xlfn.AGGREGATE(15, 6, ROW(Kintoneデータ抽出!$K$2:$K$5000) / ((Kintoneデータ抽出!$K$2:$K$5000="小規模") + (Kintoneデータ抽出!$K$2:$K$5000="認可")), ROW(A3))),""), "")} | P14: {=IFERROR(IF(INDEX(Kintoneデータ抽出!L:L, _xlfn.AGGREGATE(15, 6, ROW(Kintoneデータ抽出!$K$2:$K$5000) / ((Kintoneデータ抽出!$K$2:$K$5000="院内")), ROW(A3)))<>"", IF(COUNTIF(INDEX(Kintoneデータ抽出!L:L, _xlfn.AGGREGATE(15, 6, ROW(Kintoneデータ抽出!$K$2:$K$5000) / ((Kintoneデータ抽出!$K$2:$K$5000="院内")), ROW(A3))),"*企業主導型以外*"),"", IF(COUNTIF(INDEX(Kintoneデータ抽出!L:L, _xlfn.AGGREGATE(15, 6, ROW(Kintoneデータ抽出!$K$2:$K$5000) / ((Kintoneデータ抽出!$K$2:$K$5000="院内")), ROW(A3))),"*その他*"),"", IF(COUNTIF(INDEX(Kintoneデータ抽出!L:L, _xlfn.AGGREGATE(15, 6, ROW(Kintoneデータ抽出!$K$2:$K$5000) / ((Kintoneデータ抽出!$K$2:$K$5000="院内")), ROW(A3))),"*新制度*"),"新制度","企業主導型"))),""), "")}
D15: =IF(H15<>"",D14+1,"") | F15: {=IFERROR(INDEX(Kintoneデータ抽出!A:A, _xlfn.AGGREGATE(15, 6, ROW(Kintoneデータ抽出!$K$2:$K$5000) / ((Kintoneデータ抽出!$K$2:$K$5000="小規模") + (Kintoneデータ抽出!$K$2:$K$5000="認可")), ROW(A4))), "")} | G15: {=IFERROR(INDEX(Kintoneデータ抽出!D:D, _xlfn.AGGREGATE(15, 6, ROW(Kintoneデータ抽出!$K$2:$K$5000) / ((Kintoneデータ抽出!$K$2:$K$5000="小規模") + (Kintoneデータ抽出!$K$2:$K$5000="認可")), ROW(A4))), "")} | H15: {=IFERROR(INDEX(Kintoneデータ抽出!C:C, _xlfn.AGGREGATE(15, 6, ROW(Kintoneデータ抽出!$K$2:$K$5000) / ((Kintoneデータ抽出!$K$2:$K$5000="小規模") + (Kintoneデータ抽出!$K$2:$K$5000="認可")), ROW(A4))), "")} | I15: {=IFERROR(IF(INDEX(Kintoneデータ抽出!G:G, _xlfn.AGGREGATE(15, 6, ROW(Kintoneデータ抽出!$K$2:$K$5000) / ((Kintoneデータ抽出!$K$2:$K$5000="小規模") + (Kintoneデータ抽出!$K$2:$K$5000="認可")), ROW(A4)))<>"",INDEX(Kintoneデータ抽出!G:G, _xlfn.AGGREGATE(15, 6, ROW(Kintoneデータ抽出!$K$2:$K$5000) / ((Kintoneデータ抽出!$K$2:$K$5000="小規模") + (Kintoneデータ抽出!$K$2:$K$5000="認可")), ROW(A4)))&"名",""), "")} | J15: {=IFERROR(IF(INDEX(Kintoneデータ抽出!E:E, _xlfn.AGGREGATE(15, 6, ROW(Kintoneデータ抽出!$K$2:$K$5000) / ((Kintoneデータ抽出!$K$2:$K$5000="小規模") + (Kintoneデータ抽出!$K$2:$K$5000="認可")), ROW(A4)))<>"", YEAR(INDEX(Kintoneデータ抽出!E:E, _xlfn.AGGREGATE(15, 6, ROW(Kintoneデータ抽出!$K$2:$K$5000) / ((Kintoneデータ抽出!$K$2:$K$5000="小規模") + (Kintoneデータ抽出!$K$2:$K$5000="認可")), ROW(A4))))&"年" &MONTH(INDEX(Kintoneデータ抽出!E:E, _xlfn.AGGREGATE(15, 6, ROW(Kintoneデータ抽出!$K$2:$K$5000) / ((Kintoneデータ抽出!$K$2:$K$5000="小規模") + (Kintoneデータ抽出!$K$2:$K$5000="認可")), ROW(A4))))&"月" &DAY(INDEX(Kintoneデータ抽出!E:E, _xlfn.AGGREGATE(15, 6, ROW(Kintoneデータ抽出!$K$2:$K$5000) / ((Kintoneデータ抽出!$K$2:$K$5000="小規模") + (Kintoneデータ抽出!$K$2:$K$5000="認可")), ROW(A4))))&"日",""), "")} | K15: {=IFERROR(IF(INDEX(Kintoneデータ抽出!F:F, _xlfn.AGGREGATE(15, 6, ROW(Kintoneデータ抽出!$K$2:$K$5000) / ((Kintoneデータ抽出!$K$2:$K$5000="小規模") + (Kintoneデータ抽出!$K$2:$K$5000="認可")), ROW(A4)))<>"", VLOOKUP(INDEX(Kintoneデータ抽出!F:F, _xlfn.AGGREGATE(15, 6, ROW(Kintoneデータ抽出!$K$2:$K$5000) / ((Kintoneデータ抽出!$K$2:$K$5000="小規模") + (Kintoneデータ抽出!$K$2:$K$5000="認可")), ROW(A4))),基本開園日の表記!$A$2:$B$13,2,FALSE),""), "")} | L15: {=IFERROR(IF(INDEX(Kintoneデータ抽出!F:F, _xlfn.AGGREGATE(15, 6, ROW(Kintoneデータ抽出!$K$2:$K$5000) / ((Kintoneデータ抽出!$K$2:$K$5000="小規模") + (Kintoneデータ抽出!$K$2:$K$5000="認可")), ROW(A4)))<>"", IF(COUNTIF(INDEX(Kintoneデータ抽出!F:F, _xlfn.AGGREGATE(15, 6, ROW(Kintoneデータ抽出!$K$2:$K$5000) / ((Kintoneデータ抽出!$K$2:$K$5000="小規模") + (Kintoneデータ抽出!$K$2:$K$5000="認可")), ROW(A4))),"*あり*"),"夜間",""),""), "")} | M15: {=IFERROR(IF(INDEX(Kintoneデータ抽出!I:I, _xlfn.AGGREGATE(15, 6, ROW(Kintoneデータ抽出!$K$2:$K$5000) / ((Kintoneデータ抽出!$K$2:$K$5000="小規模") + (Kintoneデータ抽出!$K$2:$K$5000="認可")), ROW(A4)))<>"", IF(COUNTIF(INDEX(Kintoneデータ抽出!I:I, _xlfn.AGGREGATE(15, 6, ROW(Kintoneデータ抽出!$K$2:$K$5000) / ((Kintoneデータ抽出!$K$2:$K$5000="小規模") + (Kintoneデータ抽出!$K$2:$K$5000="認可")), ROW(A4))),"*あり*"),"学童",""),""), "")} | N15: {=IFERROR(IF(INDEX(Kintoneデータ抽出!H:H, _xlfn.AGGREGATE(15, 6, ROW(Kintoneデータ抽出!$K$2:$K$5000) / ((Kintoneデータ抽出!$K$2:$K$5000="小規模") + (Kintoneデータ抽出!$K$2:$K$5000="認可")), ROW(A4)))<>"", IF(COUNTIF(INDEX(Kintoneデータ抽出!H:H, _xlfn.AGGREGATE(15, 6, ROW(Kintoneデータ抽出!$K$2:$K$5000) / ((Kintoneデータ抽出!$K$2:$K$5000="小規模") + (Kintoneデータ抽出!$K$2:$K$5000="認可")), ROW(A4))),"*あり*"),"病児",""),""), "")} | O15: {=IFERROR( IF(INDEX(Kintoneデータ抽出!M:M, _xlfn.AGGREGATE(15, 6, ROW(Kintoneデータ抽出!$K$2:$K$5000) / ((Kintoneデータ抽出!$K$2:$K$5000="小規模") + (Kintoneデータ抽出!$K$2:$K$5000="認可")), ROW(A4)))<>0,INDEX(Kintoneデータ抽出!M:M, _xlfn.AGGREGATE(15, 6, ROW(Kintoneデータ抽出!$K$2:$K$5000) / ((Kintoneデータ抽出!$K$2:$K$5000="小規模") + (Kintoneデータ抽出!$K$2:$K$5000="認可")), ROW(A4))),""), "")} | P15: {=IFERROR(IF(INDEX(Kintoneデータ抽出!L:L, _xlfn.AGGREGATE(15, 6, ROW(Kintoneデータ抽出!$K$2:$K$5000) / ((Kintoneデータ抽出!$K$2:$K$5000="院内")), ROW(A4)))<>"", IF(COUNTIF(INDEX(Kintoneデータ抽出!L:L, _xlfn.AGGREGATE(15, 6, ROW(Kintoneデータ抽出!$K$2:$K$5000) / ((Kintoneデータ抽出!$K$2:$K$5000="院内")), ROW(A4))),"*企業主導型以外*"),"", IF(COUNTIF(INDEX(Kintoneデータ抽出!L:L, _xlfn.AGGREGATE(15, 6, ROW(Kintoneデータ抽出!$K$2:$K$5000) / ((Kintoneデータ抽出!$K$2:$K$5000="院内")), ROW(A4))),"*その他*"),"", IF(COUNTIF(INDEX(Kintoneデータ抽出!L:L, _xlfn.AGGREGATE(15, 6, ROW(Kintoneデータ抽出!$K$2:$K$5000) / ((Kintoneデータ抽出!$K$2:$K$5000="院内")), ROW(A4))),"*新制度*"),"新制度","企業主導型"))),""), "")}
D16: =IF(H16<>"",D15+1,"") | F16: {=IFERROR(INDEX(Kintoneデータ抽出!A:A, _xlfn.AGGREGATE(15, 6, ROW(Kintoneデータ抽出!$K$2:$K$5000) / ((Kintoneデータ抽出!$K$2:$K$5000="小規模") + (Kintoneデータ抽出!$K$2:$K$5000="認可")), ROW(A5))), "")} | G16: {=IFERROR(INDEX(Kintoneデータ抽出!D:D, _xlfn.AGGREGATE(15, 6, ROW(Kintoneデータ抽出!$K$2:$K$5000) / ((Kintoneデータ抽出!$K$2:$K$5000="小規模") + (Kintoneデータ抽出!$K$2:$K$5000="認可")), ROW(A5))), "")} | H16: {=IFERROR(INDEX(Kintoneデータ抽出!C:C, _xlfn.AGGREGATE(15, 6, ROW(Kintoneデータ抽出!$K$2:$K$5000) / ((Kintoneデータ抽出!$K$2:$K$5000="小規模") + (Kintoneデータ抽出!$K$2:$K$5000="認可")), ROW(A5))), "")} | I16: {=IFERROR(IF(INDEX(Kintoneデータ抽出!G:G, _xlfn.AGGREGATE(15, 6, ROW(Kintoneデータ抽出!$K$2:$K$5000) / ((Kintoneデータ抽出!$K$2:$K$5000="小規模") + (Kintoneデータ抽出!$K$2:$K$5000="認可")), ROW(A5)))<>"",INDEX(Kintoneデータ抽出!G:G, _xlfn.AGGREGATE(15, 6, ROW(Kintoneデータ抽出!$K$2:$K$5000) / ((Kintoneデータ抽出!$K$2:$K$5000="小規模") + (Kintoneデータ抽出!$K$2:$K$5000="認可")), ROW(A5)))&"名",""), "")} | J16: {=IFERROR(IF(INDEX(Kintoneデータ抽出!E:E, _xlfn.AGGREGATE(15, 6, ROW(Kintoneデータ抽出!$K$2:$K$5000) / ((Kintoneデータ抽出!$K$2:$K$5000="小規模") + (Kintoneデータ抽出!$K$2:$K$5000="認可")), ROW(A5)))<>"", YEAR(INDEX(Kintoneデータ抽出!E:E, _xlfn.AGGREGATE(15, 6, ROW(Kintoneデータ抽出!$K$2:$K$5000) / ((Kintoneデータ抽出!$K$2:$K$5000="小規模") + (Kintoneデータ抽出!$K$2:$K$5000="認可")), ROW(A5))))&"年" &MONTH(INDEX(Kintoneデータ抽出!E:E, _xlfn.AGGREGATE(15, 6, ROW(Kintoneデータ抽出!$K$2:$K$5000) / ((Kintoneデータ抽出!$K$2:$K$5000="小規模") + (Kintoneデータ抽出!$K$2:$K$5000="認可")), ROW(A5))))&"月" &DAY(INDEX(Kintoneデータ抽出!E:E, _xlfn.AGGREGATE(15, 6, ROW(Kintoneデータ抽出!$K$2:$K$5000) / ((Kintoneデータ抽出!$K$2:$K$5000="小規模") + (Kintoneデータ抽出!$K$2:$K$5000="認可")), ROW(A5))))&"日",""), "")} | K16: {=IFERROR(IF(INDEX(Kintoneデータ抽出!F:F, _xlfn.AGGREGATE(15, 6, ROW(Kintoneデータ抽出!$K$2:$K$5000) / ((Kintoneデータ抽出!$K$2:$K$5000="小規模") + (Kintoneデータ抽出!$K$2:$K$5000="認可")), ROW(A5)))<>"", VLOOKUP(INDEX(Kintoneデータ抽出!F:F, _xlfn.AGGREGATE(15, 6, ROW(Kintoneデータ抽出!$K$2:$K$5000) / ((Kintoneデータ抽出!$K$2:$K$5000="小規模") + (Kintoneデータ抽出!$K$2:$K$5000="認可")), ROW(A5))),基本開園日の表記!$A$2:$B$13,2,FALSE),""), "")} | L16: {=IFERROR(IF(INDEX(Kintoneデータ抽出!F:F, _xlfn.AGGREGATE(15, 6, ROW(Kintoneデータ抽出!$K$2:$K$5000) / ((Kintoneデータ抽出!$K$2:$K$5000="小規模") + (Kintoneデータ抽出!$K$2:$K$5000="認可")), ROW(A5)))<>"", IF(COUNTIF(INDEX(Kintoneデータ抽出!F:F, _xlfn.AGGREGATE(15, 6, ROW(Kintoneデータ抽出!$K$2:$K$5000) / ((Kintoneデータ抽出!$K$2:$K$5000="小規模") + (Kintoneデータ抽出!$K$2:$K$5000="認可")), ROW(A5))),"*あり*"),"夜間",""),""), "")} | M16: {=IFERROR(IF(INDEX(Kintoneデータ抽出!I:I, _xlfn.AGGREGATE(15, 6, ROW(Kintoneデータ抽出!$K$2:$K$5000) / ((Kintoneデータ抽出!$K$2:$K$5000="小規模") + (Kintoneデータ抽出!$K$2:$K$5000="認可")), ROW(A5)))<>"", IF(COUNTIF(INDEX(Kintoneデータ抽出!I:I, _xlfn.AGGREGATE(15, 6, ROW(Kintoneデータ抽出!$K$2:$K$5000) / ((Kintoneデータ抽出!$K$2:$K$5000="小規模") + (Kintoneデータ抽出!$K$2:$K$5000="認可")), ROW(A5))),"*あり*"),"学童",""),""), "")} | N16: {=IFERROR(IF(INDEX(Kintoneデータ抽出!H:H, _xlfn.AGGREGATE(15, 6, ROW(Kintoneデータ抽出!$K$2:$K$5000) / ((Kintoneデータ抽出!$K$2:$K$5000="小規模") + (Kintoneデータ抽出!$K$2:$K$5000="認可")), ROW(A5)))<>"", IF(COUNTIF(INDEX(Kintoneデータ抽出!H:H, _xlfn.AGGREGATE(15, 6, ROW(Kintoneデータ抽出!$K$2:$K$5000) / ((Kintoneデータ抽出!$K$2:$K$5000="小規模") + (Kintoneデータ抽出!$K$2:$K$5000="認可")), ROW(A5))),"*あり*"),"病児",""),""), "")} | O16: {=IFERROR( IF(INDEX(Kintoneデータ抽出!M:M, _xlfn.AGGREGATE(15, 6, ROW(Kintoneデータ抽出!$K$2:$K$5000) / ((Kintoneデータ抽出!$K$2:$K$5000="小規模") + (Kintoneデータ抽出!$K$2:$K$5000="認可")), ROW(A5)))<>0,INDEX(Kintoneデータ抽出!M:M, _xlfn.AGGREGATE(15, 6, ROW(Kintoneデータ抽出!$K$2:$K$5000) / ((Kintoneデータ抽出!$K$2:$K$5000="小規模") + (Kintoneデータ抽出!$K$2:$K$5000="認可")), ROW(A5))),""), "")} | P16: {=IFERROR(IF(INDEX(Kintoneデータ抽出!L:L, _xlfn.AGGREGATE(15, 6, ROW(Kintoneデータ抽出!$K$2:$K$5000) / ((Kintoneデータ抽出!$K$2:$K$5000="院内")), ROW(A5)))<>"", IF(COUNTIF(INDEX(Kintoneデータ抽出!L:L, _xlfn.AGGREGATE(15, 6, ROW(Kintoneデータ抽出!$K$2:$K$5000) / ((Kintoneデータ抽出!$K$2:$K$5000="院内")), ROW(A5))),"*企業主導型以外*"),"", IF(COUNTIF(INDEX(Kintoneデータ抽出!L:L, _xlfn.AGGREGATE(15, 6, ROW(Kintoneデータ抽出!$K$2:$K$5000) / ((Kintoneデータ抽出!$K$2:$K$5000="院内")), ROW(A5))),"*その他*"),"", IF(COUNTIF(INDEX(Kintoneデータ抽出!L:L, _xlfn.AGGREGATE(15, 6, ROW(Kintoneデータ抽出!$K$2:$K$5000) / ((Kintoneデータ抽出!$K$2:$K$5000="院内")), ROW(A5))),"*新制度*"),"新制度","企業主導型"))),""), "")}
B17: 関 東 | D17: =IF(H17<>"",D16+1,"") | F17: {=IFERROR(INDEX(Kintoneデータ抽出!A:A, _xlfn.AGGREGATE(15, 6, ROW(Kintoneデータ抽出!$K$2:$K$5000) / ((Kintoneデータ抽出!$K$2:$K$5000="小規模") + (Kintoneデータ抽出!$K$2:$K$5000="認可")), ROW(A6))), "")} | G17: {=IFERROR(INDEX(Kintoneデータ抽出!D:D, _xlfn.AGGREGATE(15, 6, ROW(Kintoneデータ抽出!$K$2:$K$5000) / ((Kintoneデータ抽出!$K$2:$K$5000="小規模") + (Kintoneデータ抽出!$K$2:$K$5000="認可")), ROW(A6))), "")} | H17: {=IFERROR(INDEX(Kintoneデータ抽出!C:C, _xlfn.AGGREGATE(15, 6, ROW(Kintoneデータ抽出!$K$2:$K$5000) / ((Kintoneデータ抽出!$K$2:$K$5000="小規模") + (Kintoneデータ抽出!$K$2:$K$5000="認可")), ROW(A6))), "")} | I17: {=IFERROR(IF(INDEX(Kintoneデータ抽出!G:G, _xlfn.AGGREGATE(15, 6, ROW(Kintoneデータ抽出!$K$2:$K$5000) / ((Kintoneデータ抽出!$K$2:$K$5000="小規模") + (Kintoneデータ抽出!$K$2:$K$5000="認可")), ROW(A6)))<>"",INDEX(Kintoneデータ抽出!G:G, _xlfn.AGGREGATE(15, 6, ROW(Kintoneデータ抽出!$K$2:$K$5000) / ((Kintoneデータ抽出!$K$2:$K$5000="小規模") + (Kintoneデータ抽出!$K$2:$K$5000="認可")), ROW(A6)))&"名",""), "")} | J17: {=IFERROR(IF(INDEX(Kintoneデータ抽出!E:E, _xlfn.AGGREGATE(15, 6, ROW(Kintoneデータ抽出!$K$2:$K$5000) / ((Kintoneデータ抽出!$K$2:$K$5000="小規模") + (Kintoneデータ抽出!$K$2:$K$5000="認可")), ROW(A6)))<>"", YEAR(INDEX(Kintoneデータ抽出!E:E, _xlfn.AGGREGATE(15, 6, ROW(Kintoneデータ抽出!$K$2:$K$5000) / ((Kintoneデータ抽出!$K$2:$K$5000="小規模") + (Kintoneデータ抽出!$K$2:$K$5000="認可")), ROW(A6))))&"年" &MONTH(INDEX(Kintoneデータ抽出!E:E, _xlfn.AGGREGATE(15, 6, ROW(Kintoneデータ抽出!$K$2:$K$5000) / ((Kintoneデータ抽出!$K$2:$K$5000="小規模") + (Kintoneデータ抽出!$K$2:$K$5000="認可")), ROW(A6))))&"月" &DAY(INDEX(Kintoneデータ抽出!E:E, _xlfn.AGGREGATE(15, 6, ROW(Kintoneデータ抽出!$K$2:$K$5000) / ((Kintoneデータ抽出!$K$2:$K$5000="小規模") + (Kintoneデータ抽出!$K$2:$K$5000="認可")), ROW(A6))))&"日",""), "")} | K17: {=IFERROR(IF(INDEX(Kintoneデータ抽出!F:F, _xlfn.AGGREGATE(15, 6, ROW(Kintoneデータ抽出!$K$2:$K$5000) / ((Kintoneデータ抽出!$K$2:$K$5000="小規模") + (Kintoneデータ抽出!$K$2:$K$5000="認可")), ROW(A6)))<>"", VLOOKUP(INDEX(Kintoneデータ抽出!F:F, _xlfn.AGGREGATE(15, 6, ROW(Kintoneデータ抽出!$K$2:$K$5000) / ((Kintoneデータ抽出!$K$2:$K$5000="小規模") + (Kintoneデータ抽出!$K$2:$K$5000="認可")), ROW(A6))),基本開園日の表記!$A$2:$B$13,2,FALSE),""), "")} | L17: {=IFERROR(IF(INDEX(Kintoneデータ抽出!F:F, _xlfn.AGGREGATE(15, 6, ROW(Kintoneデータ抽出!$K$2:$K$5000) / ((Kintoneデータ抽出!$K$2:$K$5000="小規模") + (Kintoneデータ抽出!$K$2:$K$5000="認可")), ROW(A6)))<>"", IF(COUNTIF(INDEX(Kintoneデータ抽出!F:F, _xlfn.AGGREGATE(15, 6, ROW(Kintoneデータ抽出!$K$2:$K$5000) / ((Kintoneデータ抽出!$K$2:$K$5000="小規模") + (Kintoneデータ抽出!$K$2:$K$5000="認可")), ROW(A6))),"*あり*"),"夜間",""),""), "")} | M17: {=IFERROR(IF(INDEX(Kintoneデータ抽出!I:I, _xlfn.AGGREGATE(15, 6, ROW(Kintoneデータ抽出!$K$2:$K$5000) / ((Kintoneデータ抽出!$K$2:$K$5000="小規模") + (Kintoneデータ抽出!$K$2:$K$5000="認可")), ROW(A6)))<>"", IF(COUNTIF(INDEX(Kintoneデータ抽出!I:I, _xlfn.AGGREGATE(15, 6, ROW(Kintoneデータ抽出!$K$2:$K$5000) / ((Kintoneデータ抽出!$K$2:$K$5000="小規模") + (Kintoneデータ抽出!$K$2:$K$5000="認可")), ROW(A6))),"*あり*"),"学童",""),""), "")} | N17: {=IFERROR(IF(INDEX(Kintoneデータ抽出!H:H, _xlfn.AGGREGATE(15, 6, ROW(Kintoneデータ抽出!$K$2:$K$5000) / ((Kintoneデータ抽出!$K$2:$K$5000="小規模") + (Kintoneデータ抽出!$K$2:$K$5000="認可")), ROW(A6)))<>"", IF(COUNTIF(INDEX(Kintoneデータ抽出!H:H, _xlfn.AGGREGATE(15, 6, ROW(Kintoneデータ抽出!$K$2:$K$5000) / ((Kintoneデータ抽出!$K$2:$K$5000="小規模") + (Kintoneデータ抽出!$K$2:$K$5000="認可")), ROW(A6))),"*あり*"),"病児",""),""), "")} | O17: {=IFERROR( IF(INDEX(Kintoneデータ抽出!M:M, _xlfn.AGGREGATE(15, 6, ROW(Kintoneデータ抽出!$K$2:$K$5000) / ((Kintoneデータ抽出!$K$2:$K$5000="小規模") + (Kintoneデータ抽出!$K$2:$K$5000="認可")), ROW(A6)))<>0,INDEX(Kintoneデータ抽出!M:M, _xlfn.AGGREGATE(15, 6, ROW(Kintoneデータ抽出!$K$2:$K$5000) / ((Kintoneデータ抽出!$K$2:$K$5000="小規模") + (Kintoneデータ抽出!$K$2:$K$5000="認可")), ROW(A6))),""), "")} | P17: {=IFERROR(IF(INDEX(Kintoneデータ抽出!L:L, _xlfn.AGGREGATE(15, 6, ROW(Kintoneデータ抽出!$K$2:$K$5000) / ((Kintoneデータ抽出!$K$2:$K$5000="院内")), ROW(A6)))<>"", IF(COUNTIF(INDEX(Kintoneデータ抽出!L:L, _xlfn.AGGREGATE(15, 6, ROW(Kintoneデータ抽出!$K$2:$K$5000) / ((Kintoneデータ抽出!$K$2:$K$5000="院内")), ROW(A6))),"*企業主導型以外*"),"", IF(COUNTIF(INDEX(Kintoneデータ抽出!L:L, _xlfn.AGGREGATE(15, 6, ROW(Kintoneデータ抽出!$K$2:$K$5000) / ((Kintoneデータ抽出!$K$2:$K$5000="院内")), ROW(A6))),"*その他*"),"", IF(COUNTIF(INDEX(Kintoneデータ抽出!L:L, _xlfn.AGGREGATE(15, 6, ROW(Kintoneデータ抽出!$K$2:$K$5000) / ((Kintoneデータ抽出!$K$2:$K$5000="院内")), ROW(A6))),"*新制度*"),"新制度","企業主導型"))),""), "")}
B18: 沖 縄 | D18: =IF(H18<>"",D17+1,"") | F18: {=IFERROR(INDEX(Kintoneデータ抽出!A:A, _xlfn.AGGREGATE(15, 6, ROW(Kintoneデータ抽出!$K$2:$K$5000) / ((Kintoneデータ抽出!$K$2:$K$5000="小規模") + (Kintoneデータ抽出!$K$2:$K$5000="認可")), ROW(A7))), "")} | G18: {=IFERROR(INDEX(Kintoneデータ抽出!D:D, _xlfn.AGGREGATE(15, 6, ROW(Kintoneデータ抽出!$K$2:$K$5000) / ((Kintoneデータ抽出!$K$2:$K$5000="小規模") + (Kintoneデータ抽出!$K$2:$K$5000="認可")), ROW(A7))), "")} | H18: {=IFERROR(INDEX(Kintoneデータ抽出!C:C, _xlfn.AGGREGATE(15, 6, ROW(Kintoneデータ抽出!$K$2:$K$5000) / ((Kintoneデータ抽出!$K$2:$K$5000="小規模") + (Kintoneデータ抽出!$K$2:$K$5000="認可")), ROW(A7))), "")} | I18: {=IFERROR(IF(INDEX(Kintoneデータ抽出!G:G, _xlfn.AGGREGATE(15, 6, ROW(Kintoneデータ抽出!$K$2:$K$5000) / ((Kintoneデータ抽出!$K$2:$K$5000="小規模") + (Kintoneデータ抽出!$K$2:$K$5000="認可")), ROW(A7)))<>"",INDEX(Kintoneデータ抽出!G:G, _xlfn.AGGREGATE(15, 6, ROW(Kintoneデータ抽出!$K$2:$K$5000) / ((Kintoneデータ抽出!$K$2:$K$5000="小規模") + (Kintoneデータ抽出!$K$2:$K$5000="認可")), ROW(A7)))&"名",""), "")} | J18: {=IFERROR(IF(INDEX(Kintoneデータ抽出!E:E, _xlfn.AGGREGATE(15, 6, ROW(Kintoneデータ抽出!$K$2:$K$5000) / ((Kintoneデータ抽出!$K$2:$K$5000="小規模") + (Kintoneデータ抽出!$K$2:$K$5000="認可")), ROW(A7)))<>"", YEAR(INDEX(Kintoneデータ抽出!E:E, _xlfn.AGGREGATE(15, 6, ROW(Kintoneデータ抽出!$K$2:$K$5000) / ((Kintoneデータ抽出!$K$2:$K$5000="小規模") + (Kintoneデータ抽出!$K$2:$K$5000="認可")), ROW(A7))))&"年" &MONTH(INDEX(Kintoneデータ抽出!E:E, _xlfn.AGGREGATE(15, 6, ROW(Kintoneデータ抽出!$K$2:$K$5000) / ((Kintoneデータ抽出!$K$2:$K$5000="小規模") + (Kintoneデータ抽出!$K$2:$K$5000="認可")), ROW(A7))))&"月" &DAY(INDEX(Kintoneデータ抽出!E:E, _xlfn.AGGREGATE(15, 6, ROW(Kintoneデータ抽出!$K$2:$K$5000) / ((Kintoneデータ抽出!$K$2:$K$5000="小規模") + (Kintoneデータ抽出!$K$2:$K$5000="認可")), ROW(A7))))&"日",""), "")} | K18: {=IFERROR(IF(INDEX(Kintoneデータ抽出!F:F, _xlfn.AGGREGATE(15, 6, ROW(Kintoneデータ抽出!$K$2:$K$5000) / ((Kintoneデータ抽出!$K$2:$K$5000="小規模") + (Kintoneデータ抽出!$K$2:$K$5000="認可")), ROW(A7)))<>"", VLOOKUP(INDEX(Kintoneデータ抽出!F:F, _xlfn.AGGREGATE(15, 6, ROW(Kintoneデータ抽出!$K$2:$K$5000) / ((Kintoneデータ抽出!$K$2:$K$5000="小規模") + (Kintoneデータ抽出!$K$2:$K$5000="認可")), ROW(A7))),基本開園日の表記!$A$2:$B$13,2,FALSE),""), "")} | L18: {=IFERROR(IF(INDEX(Kintoneデータ抽出!F:F, _xlfn.AGGREGATE(15, 6, ROW(Kintoneデータ抽出!$K$2:$K$5000) / ((Kintoneデータ抽出!$K$2:$K$5000="小規模") + (Kintoneデータ抽出!$K$2:$K$5000="認可")), ROW(A7)))<>"", IF(COUNTIF(INDEX(Kintoneデータ抽出!F:F, _xlfn.AGGREGATE(15, 6, ROW(Kintoneデータ抽出!$K$2:$K$5000) / ((Kintoneデータ抽出!$K$2:$K$5000="小規模") + (Kintoneデータ抽出!$K$2:$K$5000="認可")), ROW(A7))),"*あり*"),"夜間",""),""), "")} | M18: {=IFERROR(IF(INDEX(Kintoneデータ抽出!I:I, _xlfn.AGGREGATE(15, 6, ROW(Kintoneデータ抽出!$K$2:$K$5000) / ((Kintoneデータ抽出!$K$2:$K$5000="小規模") + (Kintoneデータ抽出!$K$2:$K$5000="認可")), ROW(A7)))<>"", IF(COUNTIF(INDEX(Kintoneデータ抽出!I:I, _xlfn.AGGREGATE(15, 6, ROW(Kintoneデータ抽出!$K$2:$K$5000) / ((Kintoneデータ抽出!$K$2:$K$5000="小規模") + (Kintoneデータ抽出!$K$2:$K$5000="認可")), ROW(A7))),"*あり*"),"学童",""),""), "")} | N18: {=IFERROR(IF(INDEX(Kintoneデータ抽出!H:H, _xlfn.AGGREGATE(15, 6, ROW(Kintoneデータ抽出!$K$2:$K$5000) / ((Kintoneデータ抽出!$K$2:$K$5000="小規模") + (Kintoneデータ抽出!$K$2:$K$5000="認可")), ROW(A7)))<>"", IF(COUNTIF(INDEX(Kintoneデータ抽出!H:H, _xlfn.AGGREGATE(15, 6, ROW(Kintoneデータ抽出!$K$2:$K$5000) / ((Kintoneデータ抽出!$K$2:$K$5000="小規模") + (Kintoneデータ抽出!$K$2:$K$5000="認可")), ROW(A7))),"*あり*"),"病児",""),""), "")} | O18: {=IFERROR( IF(INDEX(Kintoneデータ抽出!M:M, _xlfn.AGGREGATE(15, 6, ROW(Kintoneデータ抽出!$K$2:$K$5000) / ((Kintoneデータ抽出!$K$2:$K$5000="小規模") + (Kintoneデータ抽出!$K$2:$K$5000="認可")), ROW(A7)))<>0,INDEX(Kintoneデータ抽出!M:M, _xlfn.AGGREGATE(15, 6, ROW(Kintoneデータ抽出!$K$2:$K$5000) / ((Kintoneデータ抽出!$K$2:$K$5000="小規模") + (Kintoneデータ抽出!$K$2:$K$5000="認可")), ROW(A7))),""), "")} | P18: {=IFERROR(IF(INDEX(Kintoneデータ抽出!L:L, _xlfn.AGGREGATE(15, 6, ROW(Kintoneデータ抽出!$K$2:$K$5000) / ((Kintoneデータ抽出!$K$2:$K$5000="院内")), ROW(A7)))<>"", IF(COUNTIF(INDEX(Kintoneデータ抽出!L:L, _xlfn.AGGREGATE(15, 6, ROW(Kintoneデータ抽出!$K$2:$K$5000) / ((Kintoneデータ抽出!$K$2:$K$5000="院内")), ROW(A7))),"*企業主導型以外*"),"", IF(COUNTIF(INDEX(Kintoneデータ抽出!L:L, _xlfn.AGGREGATE(15, 6, ROW(Kintoneデータ抽出!$K$2:$K$5000) / ((Kintoneデータ抽出!$K$2:$K$5000="院内")), ROW(A7))),"*その他*"),"", IF(COUNTIF(INDEX(Kintoneデータ抽出!L:L, _xlfn.AGGREGATE(15, 6, ROW(Kintoneデータ抽出!$K$2:$K$5000) / ((Kintoneデータ抽出!$K$2:$K$5000="院内")), ROW(A7))),"*新制度*"),"新制度","企業主導型"))),""), "")}
B19: 関 東 | D19: =IF(H19<>"",D18+1,"") | F19: {=IFERROR(INDEX(Kintoneデータ抽出!A:A, _xlfn.AGGREGATE(15, 6, ROW(Kintoneデータ抽出!$K$2:$K$5000) / ((Kintoneデータ抽出!$K$2:$K$5000="小規模") + (Kintoneデータ抽出!$K$2:$K$5000="認可")), ROW(A8))), "")} | G19: {=IFERROR(INDEX(Kintoneデータ抽出!D:D, _xlfn.AGGREGATE(15, 6, ROW(Kintoneデータ抽出!$K$2:$K$5000) / ((Kintoneデータ抽出!$K$2:$K$5000="小規模") + (Kintoneデータ抽出!$K$2:$K$5000="認可")), ROW(A8))), "")} | H19: {=IFERROR(INDEX(Kintoneデータ抽出!C:C, _xlfn.AGGREGATE(15, 6, ROW(Kintoneデータ抽出!$K$2:$K$5000) / ((Kintoneデータ抽出!$K$2:$K$5000="小規模") + (Kintoneデータ抽出!$K$2:$K$5000="認可")), ROW(A8))), "")} | I19: {=IFERROR(IF(INDEX(Kintoneデータ抽出!G:G, _xlfn.AGGREGATE(15, 6, ROW(Kintoneデータ抽出!$K$2:$K$5000) / ((Kintoneデータ抽出!$K$2:$K$5000="小規模") + (Kintoneデータ抽出!$K$2:$K$5000="認可")), ROW(A8)))<>"",INDEX(Kintoneデータ抽出!G:G, _xlfn.AGGREGATE(15, 6, ROW(Kintoneデータ抽出!$K$2:$K$5000) / ((Kintoneデータ抽出!$K$2:$K$5000="小規模") + (Kintoneデータ抽出!$K$2:$K$5000="認可")), ROW(A8)))&"名",""), "")} | J19: {=IFERROR(IF(INDEX(Kintoneデータ抽出!E:E, _xlfn.AGGREGATE(15, 6, ROW(Kintoneデータ抽出!$K$2:$K$5000) / ((Kintoneデータ抽出!$K$2:$K$5000="小規模") + (Kintoneデータ抽出!$K$2:$K$5000="認可")), ROW(A8)))<>"", YEAR(INDEX(Kintoneデータ抽出!E:E, _xlfn.AGGREGATE(15, 6, ROW(Kintoneデータ抽出!$K$2:$K$5000) / ((Kintoneデータ抽出!$K$2:$K$5000="小規模") + (Kintoneデータ抽出!$K$2:$K$5000="認可")), ROW(A8))))&"年" &MONTH(INDEX(Kintoneデータ抽出!E:E, _xlfn.AGGREGATE(15, 6, ROW(Kintoneデータ抽出!$K$2:$K$5000) / ((Kintoneデータ抽出!$K$2:$K$5000="小規模") + (Kintoneデータ抽出!$K$2:$K$5000="認可")), ROW(A8))))&"月" &DAY(INDEX(Kintoneデータ抽出!E:E, _xlfn.AGGREGATE(15, 6, ROW(Kintoneデータ抽出!$K$2:$K$5000) / ((Kintoneデータ抽出!$K$2:$K$5000="小規模") + (Kintoneデータ抽出!$K$2:$K$5000="認可")), ROW(A8))))&"日",""), "")} | K19: {=IFERROR(IF(INDEX(Kintoneデータ抽出!F:F, _xlfn.AGGREGATE(15, 6, ROW(Kintoneデータ抽出!$K$2:$K$5000) / ((Kintoneデータ抽出!$K$2:$K$5000="小規模") + (Kintoneデータ抽出!$K$2:$K$5000="認可")), ROW(A8)))<>"", VLOOKUP(INDEX(Kintoneデータ抽出!F:F, _xlfn.AGGREGATE(15, 6, ROW(Kintoneデータ抽出!$K$2:$K$5000) / ((Kintoneデータ抽出!$K$2:$K$5000="小規模") + (Kintoneデータ抽出!$K$2:$K$5000="認可")), ROW(A8))),基本開園日の表記!$A$2:$B$13,2,FALSE),""), "")} | L19: {=IFERROR(IF(INDEX(Kintoneデータ抽出!F:F, _xlfn.AGGREGATE(15, 6, ROW(Kintoneデータ抽出!$K$2:$K$5000) / ((Kintoneデータ抽出!$K$2:$K$5000="小規模") + (Kintoneデータ抽出!$K$2:$K$5000="認可")), ROW(A8)))<>"", IF(COUNTIF(INDEX(Kintoneデータ抽出!F:F, _xlfn.AGGREGATE(15, 6, ROW(Kintoneデータ抽出!$K$2:$K$5000) / ((Kintoneデータ抽出!$K$2:$K$5000="小規模") + (Kintoneデータ抽出!$K$2:$K$5000="認可")), ROW(A8))),"*あり*"),"夜間",""),""), "")} | M19: {=IFERROR(IF(INDEX(Kintoneデータ抽出!I:I, _xlfn.AGGREGATE(15, 6, ROW(Kintoneデータ抽出!$K$2:$K$5000) / ((Kintoneデータ抽出!$K$2:$K$5000="小規模") + (Kintoneデータ抽出!$K$2:$K$5000="認可")), ROW(A8)))<>"", IF(COUNTIF(INDEX(Kintoneデータ抽出!I:I, _xlfn.AGGREGATE(15, 6, ROW(Kintoneデータ抽出!$K$2:$K$5000) / ((Kintoneデータ抽出!$K$2:$K$5000="小規模") + (Kintoneデータ抽出!$K$2:$K$5000="認可")), ROW(A8))),"*あり*"),"学童",""),""), "")} | N19: {=IFERROR(IF(INDEX(Kintoneデータ抽出!H:H, _xlfn.AGGREGATE(15, 6, ROW(Kintoneデータ抽出!$K$2:$K$5000) / ((Kintoneデータ抽出!$K$2:$K$5000="小規模") + (Kintoneデータ抽出!$K$2:$K$5000="認可")), ROW(A8)))<>"", IF(COUNTIF(INDEX(Kintoneデータ抽出!H:H, _xlfn.AGGREGATE(15, 6, ROW(Kintoneデータ抽出!$K$2:$K$5000) / ((Kintoneデータ抽出!$K$2:$K$5000="小規模") + (Kintoneデータ抽出!$K$2:$K$5000="認可")), ROW(A8))),"*あり*"),"病児",""),""), "")} | O19: {=IFERROR( IF(INDEX(Kintoneデータ抽出!M:M, _xlfn.AGGREGATE(15, 6, ROW(Kintoneデータ抽出!$K$2:$K$5000) / ((Kintoneデータ抽出!$K$2:$K$5000="小規模") + (Kintoneデータ抽出!$K$2:$K$5000="認可")), ROW(A8)))<>0,INDEX(Kintoneデータ抽出!M:M, _xlfn.AGGREGATE(15, 6, ROW(Kintoneデータ抽出!$K$2:$K$5000) / ((Kintoneデータ抽出!$K$2:$K$5000="小規模") + (Kintoneデータ抽出!$K$2:$K$5000="認可")), ROW(A8))),""), "")} | P19: {=IFERROR(IF(INDEX(Kintoneデータ抽出!L:L, _xlfn.AGGREGATE(15, 6, ROW(Kintoneデータ抽出!$K$2:$K$5000) / ((Kintoneデータ抽出!$K$2:$K$5000="院内")), ROW(A8)))<>"", IF(COUNTIF(INDEX(Kintoneデータ抽出!L:L, _xlfn.AGGREGATE(15, 6, ROW(Kintoneデータ抽出!$K$2:$K$5000) / ((Kintoneデータ抽出!$K$2:$K$5000="院内")), ROW(A8))),"*企業主導型以外*"),"", IF(COUNTIF(INDEX(Kintoneデータ抽出!L:L, _xlfn.AGGREGATE(15, 6, ROW(Kintoneデータ抽出!$K$2:$K$5000) / ((Kintoneデータ抽出!$K$2:$K$5000="院内")), ROW(A8))),"*その他*"),"", IF(COUNTIF(INDEX(Kintoneデータ抽出!L:L, _xlfn.AGGREGATE(15, 6, ROW(Kintoneデータ抽出!$K$2:$K$5000) / ((Kintoneデータ抽出!$K$2:$K$5000="院内")), ROW(A8))),"*新制度*"),"新制度","企業主導型"))),""), "")}
D20: =IF(H20<>"",D19+1,"") | F20: {=IFERROR(INDEX(Kintoneデータ抽出!A:A, _xlfn.AGGREGATE(15, 6, ROW(Kintoneデータ抽出!$K$2:$K$5000) / ((Kintoneデータ抽出!$K$2:$K$5000="小規模") + (Kintoneデータ抽出!$K$2:$K$5000="認可")), ROW(A9))), "")} | G20: {=IFERROR(INDEX(Kintoneデータ抽出!D:D, _xlfn.AGGREGATE(15, 6, ROW(Kintoneデータ抽出!$K$2:$K$5000) / ((Kintoneデータ抽出!$K$2:$K$5000="小規模") + (Kintoneデータ抽出!$K$2:$K$5000="認可")), ROW(A9))), "")} | H20: {=IFERROR(INDEX(Kintoneデータ抽出!C:C, _xlfn.AGGREGATE(15, 6, ROW(Kintoneデータ抽出!$K$2:$K$5000) / ((Kintoneデータ抽出!$K$2:$K$5000="小規模") + (Kintoneデータ抽出!$K$2:$K$5000="認可")), ROW(A9))), "")} | I20: {=IFERROR(IF(INDEX(Kintoneデータ抽出!G:G, _xlfn.AGGREGATE(15, 6, ROW(Kintoneデータ抽出!$K$2:$K$5000) / ((Kintoneデータ抽出!$K$2:$K$5000="小規模") + (Kintoneデータ抽出!$K$2:$K$5000="認可")), ROW(A9)))<>"",INDEX(Kintoneデータ抽出!G:G, _xlfn.AGGREGATE(15, 6, ROW(Kintoneデータ抽出!$K$2:$K$5000) / ((Kintoneデータ抽出!$K$2:$K$5000="小規模") + (Kintoneデータ抽出!$K$2:$K$5000="認可")), ROW(A9)))&"名",""), "")} | J20: {=IFERROR(IF(INDEX(Kintoneデータ抽出!E:E, _xlfn.AGGREGATE(15, 6, ROW(Kintoneデータ抽出!$K$2:$K$5000) / ((Kintoneデータ抽出!$K$2:$K$5000="小規模") + (Kintoneデータ抽出!$K$2:$K$5000="認可")), ROW(A9)))<>"", YEAR(INDEX(Kintoneデータ抽出!E:E, _xlfn.AGGREGATE(15, 6, ROW(Kintoneデータ抽出!$K$2:$K$5000) / ((Kintoneデータ抽出!$K$2:$K$5000="小規模") + (Kintoneデータ抽出!$K$2:$K$5000="認可")), ROW(A9))))&"年" &MONTH(INDEX(Kintoneデータ抽出!E:E, _xlfn.AGGREGATE(15, 6, ROW(Kintoneデータ抽出!$K$2:$K$5000) / ((Kintoneデータ抽出!$K$2:$K$5000="小規模") + (Kintoneデータ抽出!$K$2:$K$5000="認可")), ROW(A9))))&"月" &DAY(INDEX(Kintoneデータ抽出!E:E, _xlfn.AGGREGATE(15, 6, ROW(Kintoneデータ抽出!$K$2:$K$5000) / ((Kintoneデータ抽出!$K$2:$K$5000="小規模") + (Kintoneデータ抽出!$K$2:$K$5000="認可")), ROW(A9))))&"日",""), "")} | K20: {=IFERROR(IF(INDEX(Kintoneデータ抽出!F:F, _xlfn.AGGREGATE(15, 6, ROW(Kintoneデータ抽出!$K$2:$K$5000) / ((Kintoneデータ抽出!$K$2:$K$5000="小規模") + (Kintoneデータ抽出!$K$2:$K$5000="認可")), ROW(A9)))<>"", VLOOKUP(INDEX(Kintoneデータ抽出!F:F, _xlfn.AGGREGATE(15, 6, ROW(Kintoneデータ抽出!$K$2:$K$5000) / ((Kintoneデータ抽出!$K$2:$K$5000="小規模") + (Kintoneデータ抽出!$K$2:$K$5000="認可")), ROW(A9))),基本開園日の表記!$A$2:$B$13,2,FALSE),""), "")} | L20: {=IFERROR(IF(INDEX(Kintoneデータ抽出!F:F, _xlfn.AGGREGATE(15, 6, ROW(Kintoneデータ抽出!$K$2:$K$5000) / ((Kintoneデータ抽出!$K$2:$K$5000="小規模") + (Kintoneデータ抽出!$K$2:$K$5000="認可")), ROW(A9)))<>"", IF(COUNTIF(INDEX(Kintoneデータ抽出!F:F, _xlfn.AGGREGATE(15, 6, ROW(Kintoneデータ抽出!$K$2:$K$5000) / ((Kintoneデータ抽出!$K$2:$K$5000="小規模") + (Kintoneデータ抽出!$K$2:$K$5000="認可")), ROW(A9))),"*あり*"),"夜間",""),""), "")} | M20: {=IFERROR(IF(INDEX(Kintoneデータ抽出!I:I, _xlfn.AGGREGATE(15, 6, ROW(Kintoneデータ抽出!$K$2:$K$5000) / ((Kintoneデータ抽出!$K$2:$K$5000="小規模") + (Kintoneデータ抽出!$K$2:$K$5000="認可")), ROW(A9)))<>"", IF(COUNTIF(INDEX(Kintoneデータ抽出!I:I, _xlfn.AGGREGATE(15, 6, ROW(Kintoneデータ抽出!$K$2:$K$5000) / ((Kintoneデータ抽出!$K$2:$K$5000="小規模") + (Kintoneデータ抽出!$K$2:$K$5000="認可")), ROW(A9))),"*あり*"),"学童",""),""), "")} | N20: {=IFERROR(IF(INDEX(Kintoneデータ抽出!H:H, _xlfn.AGGREGATE(15, 6, ROW(Kintoneデータ抽出!$K$2:$K$5000) / ((Kintoneデータ抽出!$K$2:$K$5000="小規模") + (Kintoneデータ抽出!$K$2:$K$5000="認可")), ROW(A9)))<>"", IF(COUNTIF(INDEX(Kintoneデータ抽出!H:H, _xlfn.AGGREGATE(15, 6, ROW(Kintoneデータ抽出!$K$2:$K$5000) / ((Kintoneデータ抽出!$K$2:$K$5000="小規模") + (Kintoneデータ抽出!$K$2:$K$5000="認可")), ROW(A9))),"*あり*"),"病児",""),""), "")} | O20: {=IFERROR( IF(INDEX(Kintoneデータ抽出!M:M, _xlfn.AGGREGATE(15, 6, ROW(Kintoneデータ抽出!$K$2:$K$5000) / ((Kintoneデータ抽出!$K$2:$K$5000="小規模") + (Kintoneデータ抽出!$K$2:$K$5000="認可")), ROW(A9)))<>0,INDEX(Kintoneデータ抽出!M:M, _xlfn.AGGREGATE(15, 6, ROW(Kintoneデータ抽出!$K$2:$K$5000) / ((Kintoneデータ抽出!$K$2:$K$5000="小規模") + (Kintoneデータ抽出!$K$2:$K$5000="認可")), ROW(A9))),""), "")} | P20: {=IFERROR(IF(INDEX(Kintoneデータ抽出!L:L, _xlfn.AGGREGATE(15, 6, ROW(Kintoneデータ抽出!$K$2:$K$5000) / ((Kintoneデータ抽出!$K$2:$K$5000="院内")), ROW(A9)))<>"", IF(COUNTIF(INDEX(Kintoneデータ抽出!L:L, _xlfn.AGGREGATE(15, 6, ROW(Kintoneデータ抽出!$K$2:$K$5000) / ((Kintoneデータ抽出!$K$2:$K$5000="院内")), ROW(A9))),"*企業主導型以外*"),"", IF(COUNTIF(INDEX(Kintoneデータ抽出!L:L, _xlfn.AGGREGATE(15, 6, ROW(Kintoneデータ抽出!$K$2:$K$5000) / ((Kintoneデータ抽出!$K$2:$K$5000="院内")), ROW(A9))),"*その他*"),"", IF(COUNTIF(INDEX(Kintoneデータ抽出!L:L, _xlfn.AGGREGATE(15, 6, ROW(Kintoneデータ抽出!$K$2:$K$5000) / ((Kintoneデータ抽出!$K$2:$K$5000="院内")), ROW(A9))),"*新制度*"),"新制度","企業主導型"))),""), "")}
D21: =IF(H21<>"",D20+1,"") | F21: {=IFERROR(INDEX(Kintoneデータ抽出!A:A, _xlfn.AGGREGATE(15, 6, ROW(Kintoneデータ抽出!$K$2:$K$5000) / ((Kintoneデータ抽出!$K$2:$K$5000="小規模") + (Kintoneデータ抽出!$K$2:$K$5000="認可")), ROW(A10))), "")} | G21: {=IFERROR(INDEX(Kintoneデータ抽出!D:D, _xlfn.AGGREGATE(15, 6, ROW(Kintoneデータ抽出!$K$2:$K$5000) / ((Kintoneデータ抽出!$K$2:$K$5000="小規模") + (Kintoneデータ抽出!$K$2:$K$5000="認可")), ROW(A10))), "")} | H21: {=IFERROR(INDEX(Kintoneデータ抽出!C:C, _xlfn.AGGREGATE(15, 6, ROW(Kintoneデータ抽出!$K$2:$K$5000) / ((Kintoneデータ抽出!$K$2:$K$5000="小規模") + (Kintoneデータ抽出!$K$2:$K$5000="認可")), ROW(A10))), "")} | I21: {=IFERROR(IF(INDEX(Kintoneデータ抽出!G:G, _xlfn.AGGREGATE(15, 6, ROW(Kintoneデータ抽出!$K$2:$K$5000) / ((Kintoneデータ抽出!$K$2:$K$5000="小規模") + (Kintoneデータ抽出!$K$2:$K$5000="認可")), ROW(A10)))<>"",INDEX(Kintoneデータ抽出!G:G, _xlfn.AGGREGATE(15, 6, ROW(Kintoneデータ抽出!$K$2:$K$5000) / ((Kintoneデータ抽出!$K$2:$K$5000="小規模") + (Kintoneデータ抽出!$K$2:$K$5000="認可")), ROW(A10)))&"名",""), "")} | J21: {=IFERROR(IF(INDEX(Kintoneデータ抽出!E:E, _xlfn.AGGREGATE(15, 6, ROW(Kintoneデータ抽出!$K$2:$K$5000) / ((Kintoneデータ抽出!$K$2:$K$5000="小規模") + (Kintoneデータ抽出!$K$2:$K$5000="認可")), ROW(A10)))<>"", YEAR(INDEX(Kintoneデータ抽出!E:E, _xlfn.AGGREGATE(15, 6, ROW(Kintoneデータ抽出!$K$2:$K$5000) / ((Kintoneデータ抽出!$K$2:$K$5000="小規模") + (Kintoneデータ抽出!$K$2:$K$5000="認可")), ROW(A10))))&"年" &MONTH(INDEX(Kintoneデータ抽出!E:E, _xlfn.AGGREGATE(15, 6, ROW(Kintoneデータ抽出!$K$2:$K$5000) / ((Kintoneデータ抽出!$K$2:$K$5000="小規模") + (Kintoneデータ抽出!$K$2:$K$5000="認可")), ROW(A10))))&"月" &DAY(INDEX(Kintoneデータ抽出!E:E, _xlfn.AGGREGATE(15, 6, ROW(Kintoneデータ抽出!$K$2:$K$5000) / ((Kintoneデータ抽出!$K$2:$K$5000="小規模") + (Kintoneデータ抽出!$K$2:$K$5000="認可")), ROW(A10))))&"日",""), "")} | K21: {=IFERROR(IF(INDEX(Kintoneデータ抽出!F:F, _xlfn.AGGREGATE(15, 6, ROW(Kintoneデータ抽出!$K$2:$K$5000) / ((Kintoneデータ抽出!$K$2:$K$5000="小規模") + (Kintoneデータ抽出!$K$2:$K$5000="認可")), ROW(A10)))<>"", VLOOKUP(INDEX(Kintoneデータ抽出!F:F, _xlfn.AGGREGATE(15, 6, ROW(Kintoneデータ抽出!$K$2:$K$5000) / ((Kintoneデータ抽出!$K$2:$K$5000="小規模") + (Kintoneデータ抽出!$K$2:$K$5000="認可")), ROW(A10))),基本開園日の表記!$A$2:$B$13,2,FALSE),""), "")} | L21: {=IFERROR(IF(INDEX(Kintoneデータ抽出!F:F, _xlfn.AGGREGATE(15, 6, ROW(Kintoneデータ抽出!$K$2:$K$5000) / ((Kintoneデータ抽出!$K$2:$K$5000="小規模") + (Kintoneデータ抽出!$K$2:$K$5000="認可")), ROW(A10)))<>"", IF(COUNTIF(INDEX(Kintoneデータ抽出!F:F, _xlfn.AGGREGATE(15, 6, ROW(Kintoneデータ抽出!$K$2:$K$5000) / ((Kintoneデータ抽出!$K$2:$K$5000="小規模") + (Kintoneデータ抽出!$K$2:$K$5000="認可")), ROW(A10))),"*あり*"),"夜間",""),""), "")} | M21: {=IFERROR(IF(INDEX(Kintoneデータ抽出!I:I, _xlfn.AGGREGATE(15, 6, ROW(Kintoneデータ抽出!$K$2:$K$5000) / ((Kintoneデータ抽出!$K$2:$K$5000="小規模") + (Kintoneデータ抽出!$K$2:$K$5000="認可")), ROW(A10)))<>"", IF(COUNTIF(INDEX(Kintoneデータ抽出!I:I, _xlfn.AGGREGATE(15, 6, ROW(Kintoneデータ抽出!$K$2:$K$5000) / ((Kintoneデータ抽出!$K$2:$K$5000="小規模") + (Kintoneデータ抽出!$K$2:$K$5000="認可")), ROW(A10))),"*あり*"),"学童",""),""), "")} | N21: {=IFERROR(IF(INDEX(Kintoneデータ抽出!H:H, _xlfn.AGGREGATE(15, 6, ROW(Kintoneデータ抽出!$K$2:$K$5000) / ((Kintoneデータ抽出!$K$2:$K$5000="小規模") + (Kintoneデータ抽出!$K$2:$K$5000="認可")), ROW(A10)))<>"", IF(COUNTIF(INDEX(Kintoneデータ抽出!H:H, _xlfn.AGGREGATE(15, 6, ROW(Kintoneデータ抽出!$K$2:$K$5000) / ((Kintoneデータ抽出!$K$2:$K$5000="小規模") + (Kintoneデータ抽出!$K$2:$K$5000="認可")), ROW(A10))),"*あり*"),"病児",""),""), "")} | O21: {=IFERROR( IF(INDEX(Kintoneデータ抽出!M:M, _xlfn.AGGREGATE(15, 6, ROW(Kintoneデータ抽出!$K$2:$K$5000) / ((Kintoneデータ抽出!$K$2:$K$5000="小規模") + (Kintoneデータ抽出!$K$2:$K$5000="認可")), ROW(A10)))<>0,INDEX(Kintoneデータ抽出!M:M, _xlfn.AGGREGATE(15, 6, ROW(Kintoneデータ抽出!$K$2:$K$5000) / ((Kintoneデータ抽出!$K$2:$K$5000="小規模") + (Kintoneデータ抽出!$K$2:$K$5000="認可")), ROW(A10))),""), "")} | P21: {=IFERROR(IF(INDEX(Kintoneデータ抽出!L:L, _xlfn.AGGREGATE(15, 6, ROW(Kintoneデータ抽出!$K$2:$K$5000) / ((Kintoneデータ抽出!$K$2:$K$5000="院内")), ROW(A10)))<>"", IF(COUNTIF(INDEX(Kintoneデータ抽出!L:L, _xlfn.AGGREGATE(15, 6, ROW(Kintoneデータ抽出!$K$2:$K$5000) / ((Kintoneデータ抽出!$K$2:$K$5000="院内")), ROW(A10))),"*企業主導型以外*"),"", IF(COUNTIF(INDEX(Kintoneデータ抽出!L:L, _xlfn.AGGREGATE(15, 6, ROW(Kintoneデータ抽出!$K$2:$K$5000) / ((Kintoneデータ抽出!$K$2:$K$5000="院内")), ROW(A10))),"*その他*"),"", IF(COUNTIF(INDEX(Kintoneデータ抽出!L:L, _xlfn.AGGREGATE(15, 6, ROW(Kintoneデータ抽出!$K$2:$K$5000) / ((Kintoneデータ抽出!$K$2:$K$5000="院内")), ROW(A10))),"*新制度*"),"新制度","企業主導型"))),""), "")}
D22: =IF(H22<>"",D21+1,"") | F22: {=IFERROR(INDEX(Kintoneデータ抽出!A:A, _xlfn.AGGREGATE(15, 6, ROW(Kintoneデータ抽出!$K$2:$K$5000) / ((Kintoneデータ抽出!$K$2:$K$5000="小規模") + (Kintoneデータ抽出!$K$2:$K$5000="認可")), ROW(A11))), "")} | G22: {=IFERROR(INDEX(Kintoneデータ抽出!D:D, _xlfn.AGGREGATE(15, 6, ROW(Kintoneデータ抽出!$K$2:$K$5000) / ((Kintoneデータ抽出!$K$2:$K$5000="小規模") + (Kintoneデータ抽出!$K$2:$K$5000="認可")), ROW(A11))), "")} | H22: {=IFERROR(INDEX(Kintoneデータ抽出!C:C, _xlfn.AGGREGATE(15, 6, ROW(Kintoneデータ抽出!$K$2:$K$5000) / ((Kintoneデータ抽出!$K$2:$K$5000="小規模") + (Kintoneデータ抽出!$K$2:$K$5000="認可")), ROW(A11))), "")} | I22: {=IFERROR(IF(INDEX(Kintoneデータ抽出!G:G, _xlfn.AGGREGATE(15, 6, ROW(Kintoneデータ抽出!$K$2:$K$5000) / ((Kintoneデータ抽出!$K$2:$K$5000="小規模") + (Kintoneデータ抽出!$K$2:$K$5000="認可")), ROW(A11)))<>"",INDEX(Kintoneデータ抽出!G:G, _xlfn.AGGREGATE(15, 6, ROW(Kintoneデータ抽出!$K$2:$K$5000) / ((Kintoneデータ抽出!$K$2:$K$5000="小規模") + (Kintoneデータ抽出!$K$2:$K$5000="認可")), ROW(A11)))&"名",""), "")} | J22: {=IFERROR(IF(INDEX(Kintoneデータ抽出!E:E, _xlfn.AGGREGATE(15, 6, ROW(Kintoneデータ抽出!$K$2:$K$5000) / ((Kintoneデータ抽出!$K$2:$K$5000="小規模") + (Kintoneデータ抽出!$K$2:$K$5000="認可")), ROW(A11)))<>"", YEAR(INDEX(Kintoneデータ抽出!E:E, _xlfn.AGGREGATE(15, 6, ROW(Kintoneデータ抽出!$K$2:$K$5000) / ((Kintoneデータ抽出!$K$2:$K$5000="小規模") + (Kintoneデータ抽出!$K$2:$K$5000="認可")), ROW(A11))))&"年" &MONTH(INDEX(Kintoneデータ抽出!E:E, _xlfn.AGGREGATE(15, 6, ROW(Kintoneデータ抽出!$K$2:$K$5000) / ((Kintoneデータ抽出!$K$2:$K$5000="小規模") + (Kintoneデータ抽出!$K$2:$K$5000="認可")), ROW(A11))))&"月" &DAY(INDEX(Kintoneデータ抽出!E:E, _xlfn.AGGREGATE(15, 6, ROW(Kintoneデータ抽出!$K$2:$K$5000) / ((Kintoneデータ抽出!$K$2:$K$5000="小規模") + (Kintoneデータ抽出!$K$2:$K$5000="認可")), ROW(A11))))&"日",""), "")} | K22: {=IFERROR(IF(INDEX(Kintoneデータ抽出!F:F, _xlfn.AGGREGATE(15, 6, ROW(Kintoneデータ抽出!$K$2:$K$5000) / ((Kintoneデータ抽出!$K$2:$K$5000="小規模") + (Kintoneデータ抽出!$K$2:$K$5000="認可")), ROW(A11)))<>"", VLOOKUP(INDEX(Kintoneデータ抽出!F:F, _xlfn.AGGREGATE(15, 6, ROW(Kintoneデータ抽出!$K$2:$K$5000) / ((Kintoneデータ抽出!$K$2:$K$5000="小規模") + (Kintoneデータ抽出!$K$2:$K$5000="認可")), ROW(A11))),基本開園日の表記!$A$2:$B$13,2,FALSE),""), "")} | L22: {=IFERROR(IF(INDEX(Kintoneデータ抽出!F:F, _xlfn.AGGREGATE(15, 6, ROW(Kintoneデータ抽出!$K$2:$K$5000) / ((Kintoneデータ抽出!$K$2:$K$5000="小規模") + (Kintoneデータ抽出!$K$2:$K$5000="認可")), ROW(A11)))<>"", IF(COUNTIF(INDEX(Kintoneデータ抽出!F:F, _xlfn.AGGREGATE(15, 6, ROW(Kintoneデータ抽出!$K$2:$K$5000) / ((Kintoneデータ抽出!$K$2:$K$5000="小規模") + (Kintoneデータ抽出!$K$2:$K$5000="認可")), ROW(A11))),"*あり*"),"夜間",""),""), "")} | M22: {=IFERROR(IF(INDEX(Kintoneデータ抽出!I:I, _xlfn.AGGREGATE(15, 6, ROW(Kintoneデータ抽出!$K$2:$K$5000) / ((Kintoneデータ抽出!$K$2:$K$5000="小規模") + (Kintoneデータ抽出!$K$2:$K$5000="認可")), ROW(A11)))<>"", IF(COUNTIF(INDEX(Kintoneデータ抽出!I:I, _xlfn.AGGREGATE(15, 6, ROW(Kintoneデータ抽出!$K$2:$K$5000) / ((Kintoneデータ抽出!$K$2:$K$5000="小規模") + (Kintoneデータ抽出!$K$2:$K$5000="認可")), ROW(A11))),"*あり*"),"学童",""),""), "")} | N22: {=IFERROR(IF(INDEX(Kintoneデータ抽出!H:H, _xlfn.AGGREGATE(15, 6, ROW(Kintoneデータ抽出!$K$2:$K$5000) / ((Kintoneデータ抽出!$K$2:$K$5000="小規模") + (Kintoneデータ抽出!$K$2:$K$5000="認可")), ROW(A11)))<>"", IF(COUNTIF(INDEX(Kintoneデータ抽出!H:H, _xlfn.AGGREGATE(15, 6, ROW(Kintoneデータ抽出!$K$2:$K$5000) / ((Kintoneデータ抽出!$K$2:$K$5000="小規模") + (Kintoneデータ抽出!$K$2:$K$5000="認可")), ROW(A11))),"*あり*"),"病児",""),""), "")} | O22: {=IFERROR( IF(INDEX(Kintoneデータ抽出!M:M, _xlfn.AGGREGATE(15, 6, ROW(Kintoneデータ抽出!$K$2:$K$5000) / ((Kintoneデータ抽出!$K$2:$K$5000="小規模") + (Kintoneデータ抽出!$K$2:$K$5000="認可")), ROW(A11)))<>0,INDEX(Kintoneデータ抽出!M:M, _xlfn.AGGREGATE(15, 6, ROW(Kintoneデータ抽出!$K$2:$K$5000) / ((Kintoneデータ抽出!$K$2:$K$5000="小規模") + (Kintoneデータ抽出!$K$2:$K$5000="認可")), ROW(A11))),""), "")} | P22: {=IFERROR(IF(INDEX(Kintoneデータ抽出!L:L, _xlfn.AGGREGATE(15, 6, ROW(Kintoneデータ抽出!$K$2:$K$5000) / ((Kintoneデータ抽出!$K$2:$K$5000="院内")), ROW(A11)))<>"", IF(COUNTIF(INDEX(Kintoneデータ抽出!L:L, _xlfn.AGGREGATE(15, 6, ROW(Kintoneデータ抽出!$K$2:$K$5000) / ((Kintoneデータ抽出!$K$2:$K$5000="院内")), ROW(A11))),"*企業主導型以外*"),"", IF(COUNTIF(INDEX(Kintoneデータ抽出!L:L, _xlfn.AGGREGATE(15, 6, ROW(Kintoneデータ抽出!$K$2:$K$5000) / ((Kintoneデータ抽出!$K$2:$K$5000="院内")), ROW(A11))),"*その他*"),"", IF(COUNTIF(INDEX(Kintoneデータ抽出!L:L, _xlfn.AGGREGATE(15, 6, ROW(Kintoneデータ抽出!$K$2:$K$5000) / ((Kintoneデータ抽出!$K$2:$K$5000="院内")), ROW(A11))),"*新制度*"),"新制度","企業主導型"))),""), "")}
D23: =IF(H23<>"",D22+1,"") | F23: {=IFERROR(INDEX(Kintoneデータ抽出!A:A, _xlfn.AGGREGATE(15, 6, ROW(Kintoneデータ抽出!$K$2:$K$5000) / ((Kintoneデータ抽出!$K$2:$K$5000="小規模") + (Kintoneデータ抽出!$K$2:$K$5000="認可")), ROW(A12))), "")} | G23: {=IFERROR(INDEX(Kintoneデータ抽出!D:D, _xlfn.AGGREGATE(15, 6, ROW(Kintoneデータ抽出!$K$2:$K$5000) / ((Kintoneデータ抽出!$K$2:$K$5000="小規模") + (Kintoneデータ抽出!$K$2:$K$5000="認可")), ROW(A12))), "")} | H23: {=IFERROR(INDEX(Kintoneデータ抽出!C:C, _xlfn.AGGREGATE(15, 6, ROW(Kintoneデータ抽出!$K$2:$K$5000) / ((Kintoneデータ抽出!$K$2:$K$5000="小規模") + (Kintoneデータ抽出!$K$2:$K$5000="認可")), ROW(A12))), "")} | I23: {=IFERROR(IF(INDEX(Kintoneデータ抽出!G:G, _xlfn.AGGREGATE(15, 6, ROW(Kintoneデータ抽出!$K$2:$K$5000) / ((Kintoneデータ抽出!$K$2:$K$5000="小規模") + (Kintoneデータ抽出!$K$2:$K$5000="認可")), ROW(A12)))<>"",INDEX(Kintoneデータ抽出!G:G, _xlfn.AGGREGATE(15, 6, ROW(Kintoneデータ抽出!$K$2:$K$5000) / ((Kintoneデータ抽出!$K$2:$K$5000="小規模") + (Kintoneデータ抽出!$K$2:$K$5000="認可")), ROW(A12)))&"名",""), "")} | J23: {=IFERROR(IF(INDEX(Kintoneデータ抽出!E:E, _xlfn.AGGREGATE(15, 6, ROW(Kintoneデータ抽出!$K$2:$K$5000) / ((Kintoneデータ抽出!$K$2:$K$5000="小規模") + (Kintoneデータ抽出!$K$2:$K$5000="認可")), ROW(A12)))<>"", YEAR(INDEX(Kintoneデータ抽出!E:E, _xlfn.AGGREGATE(15, 6, ROW(Kintoneデータ抽出!$K$2:$K$5000) / ((Kintoneデータ抽出!$K$2:$K$5000="小規模") + (Kintoneデータ抽出!$K$2:$K$5000="認可")), ROW(A12))))&"年" &MONTH(INDEX(Kintoneデータ抽出!E:E, _xlfn.AGGREGATE(15, 6, ROW(Kintoneデータ抽出!$K$2:$K$5000) / ((Kintoneデータ抽出!$K$2:$K$5000="小規模") + (Kintoneデータ抽出!$K$2:$K$5000="認可")), ROW(A12))))&"月" &DAY(INDEX(Kintoneデータ抽出!E:E, _xlfn.AGGREGATE(15, 6, ROW(Kintoneデータ抽出!$K$2:$K$5000) / ((Kintoneデータ抽出!$K$2:$K$5000="小規模") + (Kintoneデータ抽出!$K$2:$K$5000="認可")), ROW(A12))))&"日",""), "")} | K23: {=IFERROR(IF(INDEX(Kintoneデータ抽出!F:F, _xlfn.AGGREGATE(15, 6, ROW(Kintoneデータ抽出!$K$2:$K$5000) / ((Kintoneデータ抽出!$K$2:$K$5000="小規模") + (Kintoneデータ抽出!$K$2:$K$5000="認可")), ROW(A12)))<>"", VLOOKUP(INDEX(Kintoneデータ抽出!F:F, _xlfn.AGGREGATE(15, 6, ROW(Kintoneデータ抽出!$K$2:$K$5000) / ((Kintoneデータ抽出!$K$2:$K$5000="小規模") + (Kintoneデータ抽出!$K$2:$K$5000="認可")), ROW(A12))),基本開園日の表記!$A$2:$B$13,2,FALSE),""), "")} | L23: {=IFERROR(IF(INDEX(Kintoneデータ抽出!F:F, _xlfn.AGGREGATE(15, 6, ROW(Kintoneデータ抽出!$K$2:$K$5000) / ((Kintoneデータ抽出!$K$2:$K$5000="小規模") + (Kintoneデータ抽出!$K$2:$K$5000="認可")), ROW(A12)))<>"", IF(COUNTIF(INDEX(Kintoneデータ抽出!F:F, _xlfn.AGGREGATE(15, 6, ROW(Kintoneデータ抽出!$K$2:$K$5000) / ((Kintoneデータ抽出!$K$2:$K$5000="小規模") + (Kintoneデータ抽出!$K$2:$K$5000="認可")), ROW(A12))),"*あり*"),"夜間",""),""), "")} | M23: {=IFERROR(IF(INDEX(Kintoneデータ抽出!I:I, _xlfn.AGGREGATE(15, 6, ROW(Kintoneデータ抽出!$K$2:$K$5000) / ((Kintoneデータ抽出!$K$2:$K$5000="小規模") + (Kintoneデータ抽出!$K$2:$K$5000="認可")), ROW(A12)))<>"", IF(COUNTIF(INDEX(Kintoneデータ抽出!I:I, _xlfn.AGGREGATE(15, 6, ROW(Kintoneデータ抽出!$K$2:$K$5000) / ((Kintoneデータ抽出!$K$2:$K$5000="小規模") + (Kintoneデータ抽出!$K$2:$K$5000="認可")), ROW(A12))),"*あり*"),"学童",""),""), "")} | N23: {=IFERROR(IF(INDEX(Kintoneデータ抽出!H:H, _xlfn.AGGREGATE(15, 6, ROW(Kintoneデータ抽出!$K$2:$K$5000) / ((Kintoneデータ抽出!$K$2:$K$5000="小規模") + (Kintoneデータ抽出!$K$2:$K$5000="認可")), ROW(A12)))<>"", IF(COUNTIF(INDEX(Kintoneデータ抽出!H:H, _xlfn.AGGREGATE(15, 6, ROW(Kintoneデータ抽出!$K$2:$K$5000) / ((Kintoneデータ抽出!$K$2:$K$5000="小規模") + (Kintoneデータ抽出!$K$2:$K$5000="認可")), ROW(A12))),"*あり*"),"病児",""),""), "")} | O23: {=IFERROR( IF(INDEX(Kintoneデータ抽出!M:M, _xlfn.AGGREGATE(15, 6, ROW(Kintoneデータ抽出!$K$2:$K$5000) / ((Kintoneデータ抽出!$K$2:$K$5000="小規模") + (Kintoneデータ抽出!$K$2:$K$5000="認可")), ROW(A12)))<>0,INDEX(Kintoneデータ抽出!M:M, _xlfn.AGGREGATE(15, 6, ROW(Kintoneデータ抽出!$K$2:$K$5000) / ((Kintoneデータ抽出!$K$2:$K$5000="小規模") + (Kintoneデータ抽出!$K$2:$K$5000="認可")), ROW(A12))),""), "")} | P23: {=IFERROR(IF(INDEX(Kintoneデータ抽出!L:L, _xlfn.AGGREGATE(15, 6, ROW(Kintoneデータ抽出!$K$2:$K$5000) / ((Kintoneデータ抽出!$K$2:$K$5000="院内")), ROW(A12)))<>"", IF(COUNTIF(INDEX(Kintoneデータ抽出!L:L, _xlfn.AGGREGATE(15, 6, ROW(Kintoneデータ抽出!$K$2:$K$5000) / ((Kintoneデータ抽出!$K$2:$K$5000="院内")), ROW(A12))),"*企業主導型以外*"),"", IF(COUNTIF(INDEX(Kintoneデータ抽出!L:L, _xlfn.AGGREGATE(15, 6, ROW(Kintoneデータ抽出!$K$2:$K$5000) / ((Kintoneデータ抽出!$K$2:$K$5000="院内")), ROW(A12))),"*その他*"),"", IF(COUNTIF(INDEX(Kintoneデータ抽出!L:L, _xlfn.AGGREGATE(15, 6, ROW(Kintoneデータ抽出!$K$2:$K$5000) / ((Kintoneデータ抽出!$K$2:$K$5000="院内")), ROW(A12))),"*新制度*"),"新制度","企業主導型"))),""), "")}
D24: =IF(H24<>"",D23+1,"") | F24: {=IFERROR(INDEX(Kintoneデータ抽出!A:A, _xlfn.AGGREGATE(15, 6, ROW(Kintoneデータ抽出!$K$2:$K$5000) / ((Kintoneデータ抽出!$K$2:$K$5000="小規模") + (Kintoneデータ抽出!$K$2:$K$5000="認可")), ROW(A13))), "")} | G24: {=IFERROR(INDEX(Kintoneデータ抽出!D:D, _xlfn.AGGREGATE(15, 6, ROW(Kintoneデータ抽出!$K$2:$K$5000) / ((Kintoneデータ抽出!$K$2:$K$5000="小規模") + (Kintoneデータ抽出!$K$2:$K$5000="認可")), ROW(A13))), "")} | H24: {=IFERROR(INDEX(Kintoneデータ抽出!C:C, _xlfn.AGGREGATE(15, 6, ROW(Kintoneデータ抽出!$K$2:$K$5000) / ((Kintoneデータ抽出!$K$2:$K$5000="小規模") + (Kintoneデータ抽出!$K$2:$K$5000="認可")), ROW(A13))), "")} | I24: {=IFERROR(IF(INDEX(Kintoneデータ抽出!G:G, _xlfn.AGGREGATE(15, 6, ROW(Kintoneデータ抽出!$K$2:$K$5000) / ((Kintoneデータ抽出!$K$2:$K$5000="小規模") + (Kintoneデータ抽出!$K$2:$K$5000="認可")), ROW(A13)))<>"",INDEX(Kintoneデータ抽出!G:G, _xlfn.AGGREGATE(15, 6, ROW(Kintoneデータ抽出!$K$2:$K$5000) / ((Kintoneデータ抽出!$K$2:$K$5000="小規模") + (Kintoneデータ抽出!$K$2:$K$5000="認可")), ROW(A13)))&"名",""), "")} | J24: {=IFERROR(IF(INDEX(Kintoneデータ抽出!E:E, _xlfn.AGGREGATE(15, 6, ROW(Kintoneデータ抽出!$K$2:$K$5000) / ((Kintoneデータ抽出!$K$2:$K$5000="小規模") + (Kintoneデータ抽出!$K$2:$K$5000="認可")), ROW(A13)))<>"", YEAR(INDEX(Kintoneデータ抽出!E:E, _xlfn.AGGREGATE(15, 6, ROW(Kintoneデータ抽出!$K$2:$K$5000) / ((Kintoneデータ抽出!$K$2:$K$5000="小規模") + (Kintoneデータ抽出!$K$2:$K$5000="認可")), ROW(A13))))&"年" &MONTH(INDEX(Kintoneデータ抽出!E:E, _xlfn.AGGREGATE(15, 6, ROW(Kintoneデータ抽出!$K$2:$K$5000) / ((Kintoneデータ抽出!$K$2:$K$5000="小規模") + (Kintoneデータ抽出!$K$2:$K$5000="認可")), ROW(A13))))&"月" &DAY(INDEX(Kintoneデータ抽出!E:E, _xlfn.AGGREGATE(15, 6, ROW(Kintoneデータ抽出!$K$2:$K$5000) / ((Kintoneデータ抽出!$K$2:$K$5000="小規模") + (Kintoneデータ抽出!$K$2:$K$5000="認可")), ROW(A13))))&"日",""), "")} | K24: {=IFERROR(IF(INDEX(Kintoneデータ抽出!F:F, _xlfn.AGGREGATE(15, 6, ROW(Kintoneデータ抽出!$K$2:$K$5000) / ((Kintoneデータ抽出!$K$2:$K$5000="小規模") + (Kintoneデータ抽出!$K$2:$K$5000="認可")), ROW(A13)))<>"", VLOOKUP(INDEX(Kintoneデータ抽出!F:F, _xlfn.AGGREGATE(15, 6, ROW(Kintoneデータ抽出!$K$2:$K$5000) / ((Kintoneデータ抽出!$K$2:$K$5000="小規模") + (Kintoneデータ抽出!$K$2:$K$5000="認可")), ROW(A13))),基本開園日の表記!$A$2:$B$13,2,FALSE),""), "")} | L24: {=IFERROR(IF(INDEX(Kintoneデータ抽出!F:F, _xlfn.AGGREGATE(15, 6, ROW(Kintoneデータ抽出!$K$2:$K$5000) / ((Kintoneデータ抽出!$K$2:$K$5000="小規模") + (Kintoneデータ抽出!$K$2:$K$5000="認可")), ROW(A13)))<>"", IF(COUNTIF(INDEX(Kintoneデータ抽出!F:F, _xlfn.AGGREGATE(15, 6, ROW(Kintoneデータ抽出!$K$2:$K$5000) / ((Kintoneデータ抽出!$K$2:$K$5000="小規模") + (Kintoneデータ抽出!$K$2:$K$5000="認可")), ROW(A13))),"*あり*"),"夜間",""),""), "")} | M24: {=IFERROR(IF(INDEX(Kintoneデータ抽出!I:I, _xlfn.AGGREGATE(15, 6, ROW(Kintoneデータ抽出!$K$2:$K$5000) / ((Kintoneデータ抽出!$K$2:$K$5000="小規模") + (Kintoneデータ抽出!$K$2:$K$5000="認可")), ROW(A13)))<>"", IF(COUNTIF(INDEX(Kintoneデータ抽出!I:I, _xlfn.AGGREGATE(15, 6, ROW(Kintoneデータ抽出!$K$2:$K$5000) / ((Kintoneデータ抽出!$K$2:$K$5000="小規模") + (Kintoneデータ抽出!$K$2:$K$5000="認可")), ROW(A13))),"*あり*"),"学童",""),""), "")} | N24: {=IFERROR(IF(INDEX(Kintoneデータ抽出!H:H, _xlfn.AGGREGATE(15, 6, ROW(Kintoneデータ抽出!$K$2:$K$5000) / ((Kintoneデータ抽出!$K$2:$K$5000="小規模") + (Kintoneデータ抽出!$K$2:$K$5000="認可")), ROW(A13)))<>"", IF(COUNTIF(INDEX(Kintoneデータ抽出!H:H, _xlfn.AGGREGATE(15, 6, ROW(Kintoneデータ抽出!$K$2:$K$5000) / ((Kintoneデータ抽出!$K$2:$K$5000="小規模") + (Kintoneデータ抽出!$K$2:$K$5000="認可")), ROW(A13))),"*あり*"),"病児",""),""), "")} | O24: {=IFERROR( IF(INDEX(Kintoneデータ抽出!M:M, _xlfn.AGGREGATE(15, 6, ROW(Kintoneデータ抽出!$K$2:$K$5000) / ((Kintoneデータ抽出!$K$2:$K$5000="小規模") + (Kintoneデータ抽出!$K$2:$K$5000="認可")), ROW(A13)))<>0,INDEX(Kintoneデータ抽出!M:M, _xlfn.AGGREGATE(15, 6, ROW(Kintoneデータ抽出!$K$2:$K$5000) / ((Kintoneデータ抽出!$K$2:$K$5000="小規模") + (Kintoneデータ抽出!$K$2:$K$5000="認可")), ROW(A13))),""), "")} | P24: {=IFERROR(IF(INDEX(Kintoneデータ抽出!L:L, _xlfn.AGGREGATE(15, 6, ROW(Kintoneデータ抽出!$K$2:$K$5000) / ((Kintoneデータ抽出!$K$2:$K$5000="院内")), ROW(A13)))<>"", IF(COUNTIF(INDEX(Kintoneデータ抽出!L:L, _xlfn.AGGREGATE(15, 6, ROW(Kintoneデータ抽出!$K$2:$K$5000) / ((Kintoneデータ抽出!$K$2:$K$5000="院内")), ROW(A13))),"*企業主導型以外*"),"", IF(COUNTIF(INDEX(Kintoneデータ抽出!L:L, _xlfn.AGGREGATE(15, 6, ROW(Kintoneデータ抽出!$K$2:$K$5000) / ((Kintoneデータ抽出!$K$2:$K$5000="院内")), ROW(A13))),"*その他*"),"", IF(COUNTIF(INDEX(Kintoneデータ抽出!L:L, _xlfn.AGGREGATE(15, 6, ROW(Kintoneデータ抽出!$K$2:$K$5000) / ((Kintoneデータ抽出!$K$2:$K$5000="院内")), ROW(A13))),"*新制度*"),"新制度","企業主導型"))),""), "")}
D25: =IF(H25<>"",D24+1,"") | F25: {=IFERROR(INDEX(Kintoneデータ抽出!A:A, _xlfn.AGGREGATE(15, 6, ROW(Kintoneデータ抽出!$K$2:$K$5000) / ((Kintoneデータ抽出!$K$2:$K$5000="小規模") + (Kintoneデータ抽出!$K$2:$K$5000="認可")), ROW(A14))), "")} | G25: {=IFERROR(INDEX(Kintoneデータ抽出!D:D, _xlfn.AGGREGATE(15, 6, ROW(Kintoneデータ抽出!$K$2:$K$5000) / ((Kintoneデータ抽出!$K$2:$K$5000="小規模") + (Kintoneデータ抽出!$K$2:$K$5000="認可")), ROW(A14))), "")} | H25: {=IFERROR(INDEX(Kintoneデータ抽出!C:C, _xlfn.AGGREGATE(15, 6, ROW(Kintoneデータ抽出!$K$2:$K$5000) / ((Kintoneデータ抽出!$K$2:$K$5000="小規模") + (Kintoneデータ抽出!$K$2:$K$5000="認可")), ROW(A14))), "")} | I25: {=IFERROR(IF(INDEX(Kintoneデータ抽出!G:G, _xlfn.AGGREGATE(15, 6, ROW(Kintoneデータ抽出!$K$2:$K$5000) / ((Kintoneデータ抽出!$K$2:$K$5000="小規模") + (Kintoneデータ抽出!$K$2:$K$5000="認可")), ROW(A14)))<>"",INDEX(Kintoneデータ抽出!G:G, _xlfn.AGGREGATE(15, 6, ROW(Kintoneデータ抽出!$K$2:$K$5000) / ((Kintoneデータ抽出!$K$2:$K$5000="小規模") + (Kintoneデータ抽出!$K$2:$K$5000="認可")), ROW(A14)))&"名",""), "")} | J25: {=IFERROR(IF(INDEX(Kintoneデータ抽出!E:E, _xlfn.AGGREGATE(15, 6, ROW(Kintoneデータ抽出!$K$2:$K$5000) / ((Kintoneデータ抽出!$K$2:$K$5000="小規模") + (Kintoneデータ抽出!$K$2:$K$5000="認可")), ROW(A14)))<>"", YEAR(INDEX(Kintoneデータ抽出!E:E, _xlfn.AGGREGATE(15, 6, ROW(Kintoneデータ抽出!$K$2:$K$5000) / ((Kintoneデータ抽出!$K$2:$K$5000="小規模") + (Kintoneデータ抽出!$K$2:$K$5000="認可")), ROW(A14))))&"年" &MONTH(INDEX(Kintoneデータ抽出!E:E, _xlfn.AGGREGATE(15, 6, ROW(Kintoneデータ抽出!$K$2:$K$5000) / ((Kintoneデータ抽出!$K$2:$K$5000="小規模") + (Kintoneデータ抽出!$K$2:$K$5000="認可")), ROW(A14))))&"月" &DAY(INDEX(Kintoneデータ抽出!E:E, _xlfn.AGGREGATE(15, 6, ROW(Kintoneデータ抽出!$K$2:$K$5000) / ((Kintoneデータ抽出!$K$2:$K$5000="小規模") + (Kintoneデータ抽出!$K$2:$K$5000="認可")), ROW(A14))))&"日",""), "")} | K25: {=IFERROR(IF(INDEX(Kintoneデータ抽出!F:F, _xlfn.AGGREGATE(15, 6, ROW(Kintoneデータ抽出!$K$2:$K$5000) / ((Kintoneデータ抽出!$K$2:$K$5000="小規模") + (Kintoneデータ抽出!$K$2:$K$5000="認可")), ROW(A14)))<>"", VLOOKUP(INDEX(Kintoneデータ抽出!F:F, _xlfn.AGGREGATE(15, 6, ROW(Kintoneデータ抽出!$K$2:$K$5000) / ((Kintoneデータ抽出!$K$2:$K$5000="小規模") + (Kintoneデータ抽出!$K$2:$K$5000="認可")), ROW(A14))),基本開園日の表記!$A$2:$B$13,2,FALSE),""), "")} | L25: {=IFERROR(IF(INDEX(Kintoneデータ抽出!F:F, _xlfn.AGGREGATE(15, 6, ROW(Kintoneデータ抽出!$K$2:$K$5000) / ((Kintoneデータ抽出!$K$2:$K$5000="小規模") + (Kintoneデータ抽出!$K$2:$K$5000="認可")), ROW(A14)))<>"", IF(COUNTIF(INDEX(Kintoneデータ抽出!F:F, _xlfn.AGGREGATE(15, 6, ROW(Kintoneデータ抽出!$K$2:$K$5000) / ((Kintoneデータ抽出!$K$2:$K$5000="小規模") + (Kintoneデータ抽出!$K$2:$K$5000="認可")), ROW(A14))),"*あり*"),"夜間",""),""), "")} | M25: {=IFERROR(IF(INDEX(Kintoneデータ抽出!I:I, _xlfn.AGGREGATE(15, 6, ROW(Kintoneデータ抽出!$K$2:$K$5000) / ((Kintoneデータ抽出!$K$2:$K$5000="小規模") + (Kintoneデータ抽出!$K$2:$K$5000="認可")), ROW(A14)))<>"", IF(COUNTIF(INDEX(Kintoneデータ抽出!I:I, _xlfn.AGGREGATE(15, 6, ROW(Kintoneデータ抽出!$K$2:$K$5000) / ((Kintoneデータ抽出!$K$2:$K$5000="小規模") + (Kintoneデータ抽出!$K$2:$K$5000="認可")), ROW(A14))),"*あり*"),"学童",""),""), "")} | N25: {=IFERROR(IF(INDEX(Kintoneデータ抽出!H:H, _xlfn.AGGREGATE(15, 6, ROW(Kintoneデータ抽出!$K$2:$K$5000) / ((Kintoneデータ抽出!$K$2:$K$5000="小規模") + (Kintoneデータ抽出!$K$2:$K$5000="認可")), ROW(A14)))<>"", IF(COUNTIF(INDEX(Kintoneデータ抽出!H:H, _xlfn.AGGREGATE(15, 6, ROW(Kintoneデータ抽出!$K$2:$K$5000) / ((Kintoneデータ抽出!$K$2:$K$5000="小規模") + (Kintoneデータ抽出!$K$2:$K$5000="認可")), ROW(A14))),"*あり*"),"病児",""),""), "")} | O25: {=IFERROR( IF(INDEX(Kintoneデータ抽出!M:M, _xlfn.AGGREGATE(15, 6, ROW(Kintoneデータ抽出!$K$2:$K$5000) / ((Kintoneデータ抽出!$K$2:$K$5000="小規模") + (Kintoneデータ抽出!$K$2:$K$5000="認可")), ROW(A14)))<>0,INDEX(Kintoneデータ抽出!M:M, _xlfn.AGGREGATE(15, 6, ROW(Kintoneデータ抽出!$K$2:$K$5000) / ((Kintoneデータ抽出!$K$2:$K$5000="小規模") + (Kintoneデータ抽出!$K$2:$K$5000="認可")), ROW(A14))),""), "")} | P25: {=IFERROR(IF(INDEX(Kintoneデータ抽出!L:L, _xlfn.AGGREGATE(15, 6, ROW(Kintoneデータ抽出!$K$2:$K$5000) / ((Kintoneデータ抽出!$K$2:$K$5000="院内")), ROW(A14)))<>"", IF(COUNTIF(INDEX(Kintoneデータ抽出!L:L, _xlfn.AGGREGATE(15, 6, ROW(Kintoneデータ抽出!$K$2:$K$5000) / ((Kintoneデータ抽出!$K$2:$K$5000="院内")), ROW(A14))),"*企業主導型以外*"),"", IF(COUNTIF(INDEX(Kintoneデータ抽出!L:L, _xlfn.AGGREGATE(15, 6, ROW(Kintoneデータ抽出!$K$2:$K$5000) / ((Kintoneデータ抽出!$K$2:$K$5000="院内")), ROW(A14))),"*その他*"),"", IF(COUNTIF(INDEX(Kintoneデータ抽出!L:L, _xlfn.AGGREGATE(15, 6, ROW(Kintoneデータ抽出!$K$2:$K$5000) / ((Kintoneデータ抽出!$K$2:$K$5000="院内")), ROW(A14))),"*新制度*"),"新制度","企業主導型"))),""), "")}
